Workbook
Name DIAS_PERIODO: 'CUADRO DE MANDO T'!$I$9

Sheet CUADRO DE MANDO T
C6: CUADRO DE MANDO LOGÍSTICA | J6: DIAS DE STOCK
C7: ROTACIÓN DE SIMCARD | E7: DÍAS DEL PERÍODO — escriba AUTO o un número fijo: | I7: AUTO | J7: MENOR O IGUAL A 7 DIAS | L7: MENOR O IGUAL A 90
C8: Inventario disponible: | E8: Días con despacho detectados en la hoja origen: | I8: =IFERROR(SUMPRODUCT(1/COUNTIF(OFFSET('DESPACHOS 20 DIAS'!$A$2,0,0,MAX(1,COUNTA('DESPACHOS 20 DIAS'!$A:$A)-1),1),OFFSET('DESPACHOS 20 DIAS'!$A$2,0,0,MAX(1,COUNTA('DESPACHOS 20 DIAS'!$A:$A)-1),1))),0) | J8: De 8 a 14 días | L8: MAYOR A 90 Y MENOR O IGUAL A 150
C9: =TODAY() | E9: Divisor aplicado al promedio diario: | I9: =IF(ISNUMBER($I$7),$I$7,IF($I$8>0,$I$8,20)) | J9: Mas de 15 días | L9: MAYOR A 150
J10: Sin rotación en el período = gris (antes se pintaba de verde)
A11: CLAVE | B11: No. | C11: CODIGO JANUS | D11: ARTICULO JANUS | E11: Tipo | F11: DESPACHO | J11: STOCK | M11: DIAS DE STOCK SIN PRODUCIR | O11: DIAS DE STOCK DISPONIBLE PRODUCIDO | Q11: DÍAS DE STOCK TOTAL | R11: ESTADO | S11: ALERTA DE PRODUCCIÓN
F12: CANAL INDIRECTO | G12: CANAL DIRECTO | H12: TOTAL DESPACHO | I12: PROMEDIO DIARIO DE DESPACHO | J12: STOCK EN PROCESO DE LIBERACIÓN | K12: EN PRODUCCIÓN | L12: STOCK SIN PRODUCIR | N12: STOCK DISPONIBLE PRODUCIDO | P12: STOCK TOTAL
A13: KITE.ESTANDAR | B13: 1 | C13: 162082 | D13: SIM KITE M2M 2FF STANDARD | E13: Blanca | F13: =SUMIFS('DESPACHOS 20 DIAS'!F:F,'DESPACHOS 20 DIAS'!D:D,$C13,'DESPACHOS 20 DIAS'!E:E,$D13,'DESPACHOS 20 DIAS'!N:N,"CANAL INDIRECTO") | G13: =SUMIFS('DESPACHOS 20 DIAS'!F:F,'DESPACHOS 20 DIAS'!D:D,$C13,'DESPACHOS 20 DIAS'!E:E,$D13,'DESPACHOS 20 DIAS'!N:N,"CANAL DIRECTO") | H13: =F13+G13 | I13: =IFERROR(H13/DIAS_PERIODO,0) | J13: 0 | K13: =SUMIFS(INVENTARIO!E:E,INVENTARIO!D:D,$C13,INVENTARIO!B:B,$D13,INVENTARIO!A:A,"PRODUCCION") | L13: =SUMIFS(INVENTARIO!E:E,INVENTARIO!D:D,$C13,INVENTARIO!B:B,$D13,INVENTARIO!A:A,"MATERIA PRIMA") | M13: =IF($I13=0,"",L13/$I13) | N13: =SUMIFS(INVENTARIO!E:E,INVENTARIO!D:D,$C13,INVENTARIO!B:B,$D13,INVENTARIO!A:A,"BODEGA CENTRAL")+SUMIFS(INVENTARIO!E:E,INVENTARIO!D:D,$C13,INVENTARIO!B:B,$D13,INVENTARIO!A:A,"DELIVERY") | O13: =IF($I13=0,"",N13/$I13) | P13: =L13+N13+K13 | Q13: =IF($I13=0,"",P13/$I13) | R13: =IF($D13="","",IF($I13=0,"SIN ROTACIÓN",IF($E13="","",IF($E13="Numerada",IF($Q13<8,"CRÍTICO",IF($Q13<15,"ALERTA","OK")),IF($Q13<=90,"CRÍTICO",IF($Q13<=150,"ALERTA","OK")))))) | S13: =IF(OR($C13="",$E13="",$I13=0),"",IF($E13="Numerada",IF(AND($O13<8,$Q13>=8),"PRODUCIR - "&TEXT($O13,"0")&" d terminado",""),IF(AND($O13<=90,$Q13>90),"PRODUCIR - "&TEXT($O13,"0")&" d terminado","")))
A14: KITE.ESTANDAR | B14: 2 | C14: 162086 | D14: SIM KITE M2M 4FF | E14: Blanca | F14: =SUMIFS('DESPACHOS 20 DIAS'!F:F,'DESPACHOS 20 DIAS'!D:D,$C14,'DESPACHOS 20 DIAS'!E:E,$D14,'DESPACHOS 20 DIAS'!N:N,"CANAL INDIRECTO") | G14: =SUMIFS('DESPACHOS 20 DIAS'!F:F,'DESPACHOS 20 DIAS'!D:D,$C14,'DESPACHOS 20 DIAS'!E:E,$D14,'DESPACHOS 20 DIAS'!N:N,"CANAL DIRECTO") | H14: =F14+G14 | I14: =IFERROR(H14/DIAS_PERIODO,0) | J14: 0 | K14: =SUMIFS(INVENTARIO!E:E,INVENTARIO!D:D,$C14,INVENTARIO!B:B,$D14,INVENTARIO!A:A,"PRODUCCION") | L14: =SUMIFS(INVENTARIO!E:E,INVENTARIO!D:D,$C14,INVENTARIO!B:B,$D14,INVENTARIO!A:A,"MATERIA PRIMA") | M14: =IF($I14=0,"",L14/$I14) | N14: =SUMIFS(INVENTARIO!E:E,INVENTARIO!D:D,$C14,INVENTARIO!B:B,$D14,INVENTARIO!A:A,"BODEGA CENTRAL")+SUMIFS(INVENTARIO!E:E,INVENTARIO!D:D,$C14,INVENTARIO!B:B,$D14,INVENTARIO!A:A,"DELIVERY") | O14: =IF($I14=0,"",N14/$I14) | P14: =L14+N14+K14 | Q14: =IF($I14=0,"",P14/$I14) | R14: =IF($D14="","",IF($I14=0,"SIN ROTACIÓN",IF($E14="","",IF($E14="Numerada",IF($Q14<8,"CRÍTICO",IF($Q14<15,"ALERTA","OK")),IF($Q14<=90,"CRÍTICO",IF($Q14<=150,"ALERTA","OK")))))) | S14: =IF(OR($C14="",$E14="",$I14=0),"",IF($E14="Numerada",IF(AND($O14<8,$Q14>=8),"PRODUCIR - "&TEXT($O14,"0")&" d terminado",""),IF(AND($O14<=90,$Q14>90),"PRODUCIR - "&TEXT($O14,"0")&" d terminado","")))
A15: KITE.ESTANDAR | B15: 3 | C15: 162439 | D15: HALFSIM KITE M2M 2FF | E15: Blanca | F15: =SUMIFS('DESPACHOS 20 DIAS'!F:F,'DESPACHOS 20 DIAS'!D:D,$C15,'DESPACHOS 20 DIAS'!E:E,$D15,'DESPACHOS 20 DIAS'!N:N,"CANAL INDIRECTO") | G15: =SUMIFS('DESPACHOS 20 DIAS'!F:F,'DESPACHOS 20 DIAS'!D:D,$C15,'DESPACHOS 20 DIAS'!E:E,$D15,'DESPACHOS 20 DIAS'!N:N,"CANAL DIRECTO") | H15: =F15+G15 | I15: =IFERROR(H15/DIAS_PERIODO,0) | J15: 0 | K15: =SUMIFS(INVENTARIO!E:E,INVENTARIO!D:D,$C15,INVENTARIO!B:B,$D15,INVENTARIO!A:A,"PRODUCCION") | L15: =SUMIFS(INVENTARIO!E:E,INVENTARIO!D:D,$C15,INVENTARIO!B:B,$D15,INVENTARIO!A:A,"MATERIA PRIMA") | M15: =IF($I15=0,"",L15/$I15) | N15: =SUMIFS(INVENTARIO!E:E,INVENTARIO!D:D,$C15,INVENTARIO!B:B,$D15,INVENTARIO!A:A,"BODEGA CENTRAL")+SUMIFS(INVENTARIO!E:E,INVENTARIO!D:D,$C15,INVENTARIO!B:B,$D15,INVENTARIO!A:A,"DELIVERY") | O15: =IF($I15=0,"",N15/$I15) | P15: =L15+N15+K15 | Q15: =IF($I15=0,"",P15/$I15) | R15: =IF($D15="","",IF($I15=0,"SIN ROTACIÓN",IF($E15="","",IF($E15="Numerada",IF($Q15<8,"CRÍTICO",IF($Q15<15,"ALERTA","OK")),IF($Q15<=90,"CRÍTICO",IF($Q15<=150,"ALERTA","OK")))))) | S15: =IF(OR($C15="",$E15="",$I15=0),"",IF($E15="Numerada",IF(AND($O15<8,$Q15>=8),"PRODUCIR - "&TEXT($O15,"0")&" d terminado",""),IF(AND($O15<=90,$Q15>90),"PRODUCIR - "&TEXT($O15,"0")&" d terminado","")))
D16: Subtotal SIM / HALFSIM KITE M2M ESTÁNDAR | E16: Blanca | F16: =SUMIFS(F$13:F$73,$A$13:$A$73,"KITE.ESTANDAR") | G16: =SUMIFS(G$13:G$73,$A$13:$A$73,"KITE.ESTANDAR") | H16: =SUMIFS(H$13:H$73,$A$13:$A$73,"KITE.ESTANDAR") | I16: =IFERROR(H16/DIAS_PERIODO,0) | J16: =SUMIFS(J$13:J$73,$A$13:$A$73,"KITE.ESTANDAR") | K16: =SUMIFS(K$13:K$73,$A$13:$A$73,"KITE.ESTANDAR") | L16: =SUMIFS(L$13:L$73,$A$13:$A$73,"KITE.ESTANDAR") | M16: =IF($I16=0,"",L16/$I16) | N16: =SUMIFS(N$13:N$73,$A$13:$A$73,"KITE.ESTANDAR") | O16: =IF($I16=0,"",N16/$I16) | P16: =SUMIFS(P$13:P$73,$A$13:$A$73,"KITE.ESTANDAR") | Q16: =IF($I16=0,"",P16/$I16) | R16: =IF($D16="","",IF($I16=0,"SIN ROTACIÓN",IF($E16="","",IF($E16="Numerada",IF($Q16<8,"CRÍTICO",IF($Q16<15,"ALERTA","OK")),IF($Q16<=90,"CRÍTICO",IF($Q16<=150,"ALERTA","OK")))))) | S16: =IF(OR($C16="",$E16="",$I16=0),"",IF($E16="Numerada",IF(AND($O16<8,$Q16>=8),"PRODUCIR - "&TEXT($O16,"0")&" d terminado",""),IF(AND($O16<=90,$Q16>90),"PRODUCIR - "&TEXT($O16,"0")&" d terminado","")))
A17: KITE.DEVCTRL | B17: 4 | C17: 162593 | D17: HALFSIM KITE M2M 3FF DEVICE CONTROL BLANCA | E17: Blanca | F17: =SUMIFS('DESPACHOS 20 DIAS'!F:F,'DESPACHOS 20 DIAS'!D:D,$C17,'DESPACHOS 20 DIAS'!E:E,$D17,'DESPACHOS 20 DIAS'!N:N,"CANAL INDIRECTO") | G17: =SUMIFS('DESPACHOS 20 DIAS'!F:F,'DESPACHOS 20 DIAS'!D:D,$C17,'DESPACHOS 20 DIAS'!E:E,$D17,'DESPACHOS 20 DIAS'!N:N,"CANAL DIRECTO") | H17: =F17+G17 | I17: =IFERROR(H17/DIAS_PERIODO,0) | J17: 0 | K17: =SUMIFS(INVENTARIO!E:E,INVENTARIO!D:D,$C17,INVENTARIO!B:B,$D17,INVENTARIO!A:A,"PRODUCCION") | L17: =SUMIFS(INVENTARIO!E:E,INVENTARIO!D:D,$C17,INVENTARIO!B:B,$D17,INVENTARIO!A:A,"MATERIA PRIMA") | M17: =IF($I17=0,"",L17/$I17) | N17: =SUMIFS(INVENTARIO!E:E,INVENTARIO!D:D,$C17,INVENTARIO!B:B,$D17,INVENTARIO!A:A,"BODEGA CENTRAL")+SUMIFS(INVENTARIO!E:E,INVENTARIO!D:D,$C17,INVENTARIO!B:B,$D17,INVENTARIO!A:A,"DELIVERY") | O17: =IF($I17=0,"",N17/$I17) | P17: =L17+N17+K17 | Q17: =IF($I17=0,"",P17/$I17) | R17: =IF($D17="","",IF($I17=0,"SIN ROTACIÓN",IF($E17="","",IF($E17="Numerada",IF($Q17<8,"CRÍTICO",IF($Q17<15,"ALERTA","OK")),IF($Q17<=90,"CRÍTICO",IF($Q17<=150,"ALERTA","OK")))))) | S17: =IF(OR($C17="",$E17="",$I17=0),"",IF($E17="Numerada",IF(AND($O17<8,$Q17>=8),"PRODUCIR - "&TEXT($O17,"0")&" d terminado",""),IF(AND($O17<=90,$Q17>90),"PRODUCIR - "&TEXT($O17,"0")&" d terminado","")))
A18: KITE.DEVCTRL | B18: 5 | C18: 162594 | D18: HALFSIM KITE M2M 2FF DEVICE CONTROL BLANCA | E18: Blanca | F18: =SUMIFS('DESPACHOS 20 DIAS'!F:F,'DESPACHOS 20 DIAS'!D:D,$C18,'DESPACHOS 20 DIAS'!E:E,$D18,'DESPACHOS 20 DIAS'!N:N,"CANAL INDIRECTO") | G18: =SUMIFS('DESPACHOS 20 DIAS'!F:F,'DESPACHOS 20 DIAS'!D:D,$C18,'DESPACHOS 20 DIAS'!E:E,$D18,'DESPACHOS 20 DIAS'!N:N,"CANAL DIRECTO") | H18: =F18+G18 | I18: =IFERROR(H18/DIAS_PERIODO,0) | J18: 0 | K18: =SUMIFS(INVENTARIO!E:E,INVENTARIO!D:D,$C18,INVENTARIO!B:B,$D18,INVENTARIO!A:A,"PRODUCCION") | L18: =SUMIFS(INVENTARIO!E:E,INVENTARIO!D:D,$C18,INVENTARIO!B:B,$D18,INVENTARIO!A:A,"MATERIA PRIMA") | M18: =IF($I18=0,"",L18/$I18) | N18: =SUMIFS(INVENTARIO!E:E,INVENTARIO!D:D,$C18,INVENTARIO!B:B,$D18,INVENTARIO!A:A,"BODEGA CENTRAL")+SUMIFS(INVENTARIO!E:E,INVENTARIO!D:D,$C18,INVENTARIO!B:B,$D18,INVENTARIO!A:A,"DELIVERY") | O18: =IF($I18=0,"",N18/$I18) | P18: =L18+N18+K18 | Q18: =IF($I18=0,"",P18/$I18) | R18: =IF($D18="","",IF($I18=0,"SIN ROTACIÓN",IF($E18="","",IF($E18="Numerada",IF($Q18<8,"CRÍTICO",IF($Q18<15,"ALERTA","OK")),IF($Q18<=90,"CRÍTICO",IF($Q18<=150,"ALERTA","OK")))))) | S18: =IF(OR($C18="",$E18="",$I18=0),"",IF($E18="Numerada",IF(AND($O18<8,$Q18>=8),"PRODUCIR - "&TEXT($O18,"0")&" d terminado",""),IF(AND($O18<=90,$Q18>90),"PRODUCIR - "&TEXT($O18,"0")&" d terminado","")))
A19: KITE.DEVCTRL | B19: 6 | C19: 162594 | D19: HALFSIM KITE M2M 2FF DEVICE CONTROL TELEFONICA | E19: Blanca | F19: =SUMIFS('DESPACHOS 20 DIAS'!F:F,'DESPACHOS 20 DIAS'!D:D,$C19,'DESPACHOS 20 DIAS'!E:E,$D19,'DESPACHOS 20 DIAS'!N:N,"CANAL INDIRECTO") | G19: =SUMIFS('DESPACHOS 20 DIAS'!F:F,'DESPACHOS 20 DIAS'!D:D,$C19,'DESPACHOS 20 DIAS'!E:E,$D19,'DESPACHOS 20 DIAS'!N:N,"CANAL DIRECTO") | H19: =F19+G19 | I19: =IFERROR(H19/DIAS_PERIODO,0) | J19: 0 | K19: =SUMIFS(INVENTARIO!E:E,INVENTARIO!D:D,$C19,INVENTARIO!B:B,$D19,INVENTARIO!A:A,"PRODUCCION") | L19: =SUMIFS(INVENTARIO!E:E,INVENTARIO!D:D,$C19,INVENTARIO!B:B,$D19,INVENTARIO!A:A,"MATERIA PRIMA") | M19: =IF($I19=0,"",L19/$I19) | N19: =SUMIFS(INVENTARIO!E:E,INVENTARIO!D:D,$C19,INVENTARIO!B:B,$D19,INVENTARIO!A:A,"BODEGA CENTRAL")+SUMIFS(INVENTARIO!E:E,INVENTARIO!D:D,$C19,INVENTARIO!B:B,$D19,INVENTARIO!A:A,"DELIVERY") | O19: =IF($I19=0,"",N19/$I19) | P19: =L19+N19+K19 | Q19: =IF($I19=0,"",P19/$I19) | R19: =IF($D19="","",IF($I19=0,"SIN ROTACIÓN",IF($E19="","",IF($E19="Numerada",IF($Q19<8,"CRÍTICO",IF($Q19<15,"ALERTA","OK")),IF($Q19<=90,"CRÍTICO",IF($Q19<=150,"ALERTA","OK")))))) | S19: =IF(OR($C19="",$E19="",$I19=0),"",IF($E19="Numerada",IF(AND($O19<8,$Q19>=8),"PRODUCIR - "&TEXT($O19,"0")&" d terminado",""),IF(AND($O19<=90,$Q19>90),"PRODUCIR - "&TEXT($O19,"0")&" d terminado","")))
A20: KITE.DEVCTRL | B20: 7 | C20: 162699 | D20: HALFSIM KITE M2M 4FF DEVICE CONTROL TELEFONICA | E20: Blanca | F20: =SUMIFS('DESPACHOS 20 DIAS'!F:F,'DESPACHOS 20 DIAS'!D:D,$C20,'DESPACHOS 20 DIAS'!E:E,$D20,'DESPACHOS 20 DIAS'!N:N,"CANAL INDIRECTO") | G20: =SUMIFS('DESPACHOS 20 DIAS'!F:F,'DESPACHOS 20 DIAS'!D:D,$C20,'DESPACHOS 20 DIAS'!E:E,$D20,'DESPACHOS 20 DIAS'!N:N,"CANAL DIRECTO") | H20: =F20+G20 | I20: =IFERROR(H20/DIAS_PERIODO,0) | J20: 0 | K20: =SUMIFS(INVENTARIO!E:E,INVENTARIO!D:D,$C20,INVENTARIO!B:B,$D20,INVENTARIO!A:A,"PRODUCCION") | L20: =SUMIFS(INVENTARIO!E:E,INVENTARIO!D:D,$C20,INVENTARIO!B:B,$D20,INVENTARIO!A:A,"MATERIA PRIMA") | M20: =IF($I20=0,"",L20/$I20) | N20: =SUMIFS(INVENTARIO!E:E,INVENTARIO!D:D,$C20,INVENTARIO!B:B,$D20,INVENTARIO!A:A,"BODEGA CENTRAL")+SUMIFS(INVENTARIO!E:E,INVENTARIO!D:D,$C20,INVENTARIO!B:B,$D20,INVENTARIO!A:A,"DELIVERY") | O20: =IF($I20=0,"",N20/$I20) | P20: =L20+N20+K20 | Q20: =IF($I20=0,"",P20/$I20) | R20: =IF($D20="","",IF($I20=0,"SIN ROTACIÓN",IF($E20="","",IF($E20="Numerada",IF($Q20<8,"CRÍTICO",IF($Q20<15,"ALERTA","OK")),IF($Q20<=90,"CRÍTICO",IF($Q20<=150,"ALERTA","OK")))))) | S20: =IF(OR($C20="",$E20="",$I20=0),"",IF($E20="Numerada",IF(AND($O20<8,$Q20>=8),"PRODUCIR - "&TEXT($O20,"0")&" d terminado",""),IF(AND($O20<=90,$Q20>90),"PRODUCIR - "&TEXT($O20,"0")&" d terminado","")))
A21: KITE.DEVCTRL | B21: 8 | C21: 162699 | D21: HALFSIM KITE M2M 4FF DEVICE CONTROL BLANCA | E21: Blanca | F21: =SUMIFS('DESPACHOS 20 DIAS'!F:F,'DESPACHOS 20 DIAS'!D:D,$C21,'DESPACHOS 20 DIAS'!E:E,$D21,'DESPACHOS 20 DIAS'!N:N,"CANAL INDIRECTO") | G21: =SUMIFS('DESPACHOS 20 DIAS'!F:F,'DESPACHOS 20 DIAS'!D:D,$C21,'DESPACHOS 20 DIAS'!E:E,$D21,'DESPACHOS 20 DIAS'!N:N,"CANAL DIRECTO") | H21: =F21+G21 | I21: =IFERROR(H21/DIAS_PERIODO,0) | J21: 0 | K21: =SUMIFS(INVENTARIO!E:E,INVENTARIO!D:D,$C21,INVENTARIO!B:B,$D21,INVENTARIO!A:A,"PRODUCCION") | L21: =SUMIFS(INVENTARIO!E:E,INVENTARIO!D:D,$C21,INVENTARIO!B:B,$D21,INVENTARIO!A:A,"MATERIA PRIMA") | M21: =IF($I21=0,"",L21/$I21) | N21: =SUMIFS(INVENTARIO!E:E,INVENTARIO!D:D,$C21,INVENTARIO!B:B,$D21,INVENTARIO!A:A,"BODEGA CENTRAL")+SUMIFS(INVENTARIO!E:E,INVENTARIO!D:D,$C21,INVENTARIO!B:B,$D21,INVENTARIO!A:A,"DELIVERY") | O21: =IF($I21=0,"",N21/$I21) | P21: =L21+N21+K21 | Q21: =IF($I21=0,"",P21/$I21) | R21: =IF($D21="","",IF($I21=0,"SIN ROTACIÓN",IF($E21="","",IF($E21="Numerada",IF($Q21<8,"CRÍTICO",IF($Q21<15,"ALERTA","OK")),IF($Q21<=90,"CRÍTICO",IF($Q21<=150,"ALERTA","OK")))))) | S21: =IF(OR($C21="",$E21="",$I21=0),"",IF($E21="Numerada",IF(AND($O21<8,$Q21>=8),"PRODUCIR - "&TEXT($O21,"0")&" d terminado",""),IF(AND($O21<=90,$Q21>90),"PRODUCIR - "&TEXT($O21,"0")&" d terminado","")))
D22: Subtotal HALFSIM KITE M2M DEVICE CONTROL | E22: Blanca | F22: =SUMIFS(F$13:F$73,$A$13:$A$73,"KITE.DEVCTRL") | G22: =SUMIFS(G$13:G$73,$A$13:$A$73,"KITE.DEVCTRL") | H22: =SUMIFS(H$13:H$73,$A$13:$A$73,"KITE.DEVCTRL") | I22: =IFERROR(H22/DIAS_PERIODO,0) | J22: =SUMIFS(J$13:J$73,$A$13:$A$73,"KITE.DEVCTRL") | K22: =SUMIFS(K$13:K$73,$A$13:$A$73,"KITE.DEVCTRL") | L22: =SUMIFS(L$13:L$73,$A$13:$A$73,"KITE.DEVCTRL") | M22: =IF($I22=0,"",L22/$I22) | N22: =SUMIFS(N$13:N$73,$A$13:$A$73,"KITE.DEVCTRL") | O22: =IF($I22=0,"",N22/$I22) | P22: =SUMIFS(P$13:P$73,$A$13:$A$73,"KITE.DEVCTRL") | Q22: =IF($I22=0,"",P22/$I22) | R22: =IF($D22="","",IF($I22=0,"SIN ROTACIÓN",IF($E22="","",IF($E22="Numerada",IF($Q22<8,"CRÍTICO",IF($Q22<15,"ALERTA","OK")),IF($Q22<=90,"CRÍTICO",IF($Q22<=150,"ALERTA","OK")))))) | S22: =IF(OR($C22="",$E22="",$I22=0),"",IF($E22="Numerada",IF(AND($O22<8,$Q22>=8),"PRODUCIR - "&TEXT($O22,"0")&" d terminado",""),IF(AND($O22<=90,$Q22>90),"PRODUCIR - "&TEXT($O22,"0")&" d terminado","")))
D23: TOTAL KITE M2M | E23: Blanca | F23: =SUMIFS(F$13:F$73,$A$13:$A$73,"KITE.*") | G23: =SUMIFS(G$13:G$73,$A$13:$A$73,"KITE.*") | H23: =SUMIFS(H$13:H$73,$A$13:$A$73,"KITE.*") | I23: =IFERROR(H23/DIAS_PERIODO,0) | J23: =SUMIFS(J$13:J$73,$A$13:$A$73,"KITE.*") | K23: =SUMIFS(K$13:K$73,$A$13:$A$73,"KITE.*") | L23: =SUMIFS(L$13:L$73,$A$13:$A$73,"KITE.*") | M23: =IF($I23=0,"",L23/$I23) | N23: =SUMIFS(N$13:N$73,$A$13:$A$73,"KITE.*") | O23: =IF($I23=0,"",N23/$I23) | P23: =SUMIFS(P$13:P$73,$A$13:$A$73,"KITE.*") | Q23: =IF($I23=0,"",P23/$I23) | R23: =IF($D23="","",IF($I23=0,"SIN ROTACIÓN",IF($E23="","",IF($E23="Numerada",IF($Q23<8,"CRÍTICO",IF($Q23<15,"ALERTA","OK")),IF($Q23<=90,"CRÍTICO",IF($Q23<=150,"ALERTA","OK")))))) | S23: =IF(OR($C23="",$E23="",$I23=0),"",IF($E23="Numerada",IF(AND($O23<8,$Q23>=8),"PRODUCIR - "&TEXT($O23,"0")&" d terminado",""),IF(AND($O23<=90,$Q23>90),"PRODUCIR - "&TEXT($O23,"0")&" d terminado","")))
A24: M2MLTE.LTE | B24: 9 | C24: 162115 | D24: SIMCARD M2M 2FF LTE | E24: Blanca | F24: =SUMIFS('DESPACHOS 20 DIAS'!F:F,'DESPACHOS 20 DIAS'!D:D,$C24,'DESPACHOS 20 DIAS'!E:E,$D24,'DESPACHOS 20 DIAS'!N:N,"CANAL INDIRECTO") | G24: =SUMIFS('DESPACHOS 20 DIAS'!F:F,'DESPACHOS 20 DIAS'!D:D,$C24,'DESPACHOS 20 DIAS'!E:E,$D24,'DESPACHOS 20 DIAS'!N:N,"CANAL DIRECTO") | H24: =F24+G24 | I24: =IFERROR(H24/DIAS_PERIODO,0) | J24: 0 | K24: =SUMIFS(INVENTARIO!E:E,INVENTARIO!D:D,$C24,INVENTARIO!B:B,$D24,INVENTARIO!A:A,"PRODUCCION") | L24: =SUMIFS(INVENTARIO!E:E,INVENTARIO!D:D,$C24,INVENTARIO!B:B,$D24,INVENTARIO!A:A,"MATERIA PRIMA") | M24: =IF($I24=0,"",L24/$I24) | N24: =SUMIFS(INVENTARIO!E:E,INVENTARIO!D:D,$C24,INVENTARIO!B:B,$D24,INVENTARIO!A:A,"BODEGA CENTRAL")+SUMIFS(INVENTARIO!E:E,INVENTARIO!D:D,$C24,INVENTARIO!B:B,$D24,INVENTARIO!A:A,"DELIVERY") | O24: =IF($I24=0,"",N24/$I24) | P24: =L24+N24+K24 | Q24: =IF($I24=0,"",P24/$I24) | R24: =IF($D24="","",IF($I24=0,"SIN ROTACIÓN",IF($E24="","",IF($E24="Numerada",IF($Q24<8,"CRÍTICO",IF($Q24<15,"ALERTA","OK")),IF($Q24<=90,"CRÍTICO",IF($Q24<=150,"ALERTA","OK")))))) | S24: =IF(OR($C24="",$E24="",$I24=0),"",IF($E24="Numerada",IF(AND($O24<8,$Q24>=8),"PRODUCIR - "&TEXT($O24,"0")&" d terminado",""),IF(AND($O24<=90,$Q24>90),"PRODUCIR - "&TEXT($O24,"0")&" d terminado","")))
A25: M2MLTE.LTE | B25: 10 | C25: 162145 | D25: HALFSIM M2M 4FF LTE | E25: Blanca | F25: =SUMIFS('DESPACHOS 20 DIAS'!F:F,'DESPACHOS 20 DIAS'!D:D,$C25,'DESPACHOS 20 DIAS'!E:E,$D25,'DESPACHOS 20 DIAS'!N:N,"CANAL INDIRECTO") | G25: =SUMIFS('DESPACHOS 20 DIAS'!F:F,'DESPACHOS 20 DIAS'!D:D,$C25,'DESPACHOS 20 DIAS'!E:E,$D25,'DESPACHOS 20 DIAS'!N:N,"CANAL DIRECTO") | H25: =F25+G25 | I25: =IFERROR(H25/DIAS_PERIODO,0) | J25: 0 | K25: =SUMIFS(INVENTARIO!E:E,INVENTARIO!D:D,$C25,INVENTARIO!B:B,$D25,INVENTARIO!A:A,"PRODUCCION") | L25: =SUMIFS(INVENTARIO!E:E,INVENTARIO!D:D,$C25,INVENTARIO!B:B,$D25,INVENTARIO!A:A,"MATERIA PRIMA") | M25: =IF($I25=0,"",L25/$I25) | N25: =SUMIFS(INVENTARIO!E:E,INVENTARIO!D:D,$C25,INVENTARIO!B:B,$D25,INVENTARIO!A:A,"BODEGA CENTRAL")+SUMIFS(INVENTARIO!E:E,INVENTARIO!D:D,$C25,INVENTARIO!B:B,$D25,INVENTARIO!A:A,"DELIVERY") | O25: =IF($I25=0,"",N25/$I25) | P25: =L25+N25+K25 | Q25: =IF($I25=0,"",P25/$I25) | R25: =IF($D25="","",IF($I25=0,"SIN ROTACIÓN",IF($E25="","",IF($E25="Numerada",IF($Q25<8,"CRÍTICO",IF($Q25<15,"ALERTA","OK")),IF($Q25<=90,"CRÍTICO",IF($Q25<=150,"ALERTA","OK")))))) | S25: =IF(OR($C25="",$E25="",$I25=0),"",IF($E25="Numerada",IF(AND($O25<8,$Q25>=8),"PRODUCIR - "&TEXT($O25,"0")&" d terminado",""),IF(AND($O25<=90,$Q25>90),"PRODUCIR - "&TEXT($O25,"0")&" d terminado","")))
A26: M2MLTE.LTE | B26: 11 | C26: 162148 | D26: SIMCARD M2M 3FF LTE | E26: Blanca | F26: =SUMIFS('DESPACHOS 20 DIAS'!F:F,'DESPACHOS 20 DIAS'!D:D,$C26,'DESPACHOS 20 DIAS'!E:E,$D26,'DESPACHOS 20 DIAS'!N:N,"CANAL INDIRECTO") | G26: =SUMIFS('DESPACHOS 20 DIAS'!F:F,'DESPACHOS 20 DIAS'!D:D,$C26,'DESPACHOS 20 DIAS'!E:E,$D26,'DESPACHOS 20 DIAS'!N:N,"CANAL DIRECTO") | H26: =F26+G26 | I26: =IFERROR(H26/DIAS_PERIODO,0) | J26: 0 | K26: =SUMIFS(INVENTARIO!E:E,INVENTARIO!D:D,$C26,INVENTARIO!B:B,$D26,INVENTARIO!A:A,"PRODUCCION") | L26: =SUMIFS(INVENTARIO!E:E,INVENTARIO!D:D,$C26,INVENTARIO!B:B,$D26,INVENTARIO!A:A,"MATERIA PRIMA") | M26: =IF($I26=0,"",L26/$I26) | N26: =SUMIFS(INVENTARIO!E:E,INVENTARIO!D:D,$C26,INVENTARIO!B:B,$D26,INVENTARIO!A:A,"BODEGA CENTRAL")+SUMIFS(INVENTARIO!E:E,INVENTARIO!D:D,$C26,INVENTARIO!B:B,$D26,INVENTARIO!A:A,"DELIVERY") | O26: =IF($I26=0,"",N26/$I26) | P26: =L26+N26+K26 | Q26: =IF($I26=0,"",P26/$I26) | R26: =IF($D26="","",IF($I26=0,"SIN ROTACIÓN",IF($E26="","",IF($E26="Numerada",IF($Q26<8,"CRÍTICO",IF($Q26<15,"ALERTA","OK")),IF($Q26<=90,"CRÍTICO",IF($Q26<=150,"ALERTA","OK")))))) | S26: =IF(OR($C26="",$E26="",$I26=0),"",IF($E26="Numerada",IF(AND($O26<8,$Q26>=8),"PRODUCIR - "&TEXT($O26,"0")&" d terminado",""),IF(AND($O26<=90,$Q26>90),"PRODUCIR - "&TEXT($O26,"0")&" d terminado","")))
D27: TOTAL M2M LTE | E27: Blanca | F27: =SUMIFS(F$13:F$73,$A$13:$A$73,"M2MLTE.*") | G27: =SUMIFS(G$13:G$73,$A$13:$A$73,"M2MLTE.*") | H27: =SUMIFS(H$13:H$73,$A$13:$A$73,"M2MLTE.*") | I27: =IFERROR(H27/DIAS_PERIODO,0) | J27: =SUMIFS(J$13:J$73,$A$13:$A$73,"M2MLTE.*") | K27: =SUMIFS(K$13:K$73,$A$13:$A$73,"M2MLTE.*") | L27: =SUMIFS(L$13:L$73,$A$13:$A$73,"M2MLTE.*") | M27: =IF($I27=0,"",L27/$I27) | N27: =SUMIFS(N$13:N$73,$A$13:$A$73,"M2MLTE.*") | O27: =IF($I27=0,"",N27/$I27) | P27: =SUMIFS(P$13:P$73,$A$13:$A$73,"M2MLTE.*") | Q27: =IF($I27=0,"",P27/$I27) | R27: =IF($D27="","",IF($I27=0,"SIN ROTACIÓN",IF($E27="","",IF($E27="Numerada",IF($Q27<8,"CRÍTICO",IF($Q27<15,"ALERTA","OK")),IF($Q27<=90,"CRÍTICO",IF($Q27<=150,"ALERTA","OK")))))) | S27: =IF(OR($C27="",$E27="",$I27=0),"",IF($E27="Numerada",IF(AND($O27<8,$Q27>=8),"PRODUCIR - "&TEXT($O27,"0")&" d terminado",""),IF(AND($O27<=90,$Q27>90),"PRODUCIR - "&TEXT($O27,"0")&" d terminado","")))
A28: MOVISTAR.HALFSIM | B28: 12 | C28: 162141 | D28: HALFSIM MOVISTAR | E28: Blanca | F28: =SUMIFS('DESPACHOS 20 DIAS'!F:F,'DESPACHOS 20 DIAS'!D:D,$C28,'DESPACHOS 20 DIAS'!E:E,$D28,'DESPACHOS 20 DIAS'!N:N,"CANAL INDIRECTO") | G28: =SUMIFS('DESPACHOS 20 DIAS'!F:F,'DESPACHOS 20 DIAS'!D:D,$C28,'DESPACHOS 20 DIAS'!E:E,$D28,'DESPACHOS 20 DIAS'!N:N,"CANAL DIRECTO") | H28: =F28+G28 | I28: =IFERROR(H28/DIAS_PERIODO,0) | J28: 0 | K28: =SUMIFS(INVENTARIO!E:E,INVENTARIO!D:D,$C28,INVENTARIO!B:B,$D28,INVENTARIO!A:A,"PRODUCCION") | L28: =SUMIFS(INVENTARIO!E:E,INVENTARIO!D:D,$C28,INVENTARIO!B:B,$D28,INVENTARIO!A:A,"MATERIA PRIMA") | M28: =IF($I28=0,"",L28/$I28) | N28: =SUMIFS(INVENTARIO!E:E,INVENTARIO!D:D,$C28,INVENTARIO!B:B,$D28,INVENTARIO!A:A,"BODEGA CENTRAL")+SUMIFS(INVENTARIO!E:E,INVENTARIO!D:D,$C28,INVENTARIO!B:B,$D28,INVENTARIO!A:A,"DELIVERY") | O28: =IF($I28=0,"",N28/$I28) | P28: =L28+N28+K28 | Q28: =IF($I28=0,"",P28/$I28) | R28: =IF($D28="","",IF($I28=0,"SIN ROTACIÓN",IF($E28="","",IF($E28="Numerada",IF($Q28<8,"CRÍTICO",IF($Q28<15,"ALERTA","OK")),IF($Q28<=90,"CRÍTICO",IF($Q28<=150,"ALERTA","OK")))))) | S28: =IF(OR($C28="",$E28="",$I28=0),"",IF($E28="Numerada",IF(AND($O28<8,$Q28>=8),"PRODUCIR - "&TEXT($O28,"0")&" d terminado",""),IF(AND($O28<=90,$Q28>90),"PRODUCIR - "&TEXT($O28,"0")&" d terminado","")))
A29: MOVISTAR.HALFSIM | B29: 13 | C29: 1621411 | D29: HALFSIM MOVISTAR PORTABILIDAD | E29: Blanca | F29: =SUMIFS('DESPACHOS 20 DIAS'!F:F,'DESPACHOS 20 DIAS'!D:D,$C29,'DESPACHOS 20 DIAS'!E:E,$D29,'DESPACHOS 20 DIAS'!N:N,"CANAL INDIRECTO") | G29: =SUMIFS('DESPACHOS 20 DIAS'!F:F,'DESPACHOS 20 DIAS'!D:D,$C29,'DESPACHOS 20 DIAS'!E:E,$D29,'DESPACHOS 20 DIAS'!N:N,"CANAL DIRECTO") | H29: =F29+G29 | I29: =IFERROR(H29/DIAS_PERIODO,0) | J29: 0 | K29: =SUMIFS(INVENTARIO!E:E,INVENTARIO!D:D,$C29,INVENTARIO!B:B,$D29,INVENTARIO!A:A,"PRODUCCION") | L29: =SUMIFS(INVENTARIO!E:E,INVENTARIO!D:D,$C29,INVENTARIO!B:B,$D29,INVENTARIO!A:A,"MATERIA PRIMA") | M29: =IF($I29=0,"",L29/$I29) | N29: =SUMIFS(INVENTARIO!E:E,INVENTARIO!D:D,$C29,INVENTARIO!B:B,$D29,INVENTARIO!A:A,"BODEGA CENTRAL")+SUMIFS(INVENTARIO!E:E,INVENTARIO!D:D,$C29,INVENTARIO!B:B,$D29,INVENTARIO!A:A,"DELIVERY") | O29: =IF($I29=0,"",N29/$I29) | P29: =L29+N29+K29 | Q29: =IF($I29=0,"",P29/$I29) | R29: =IF($D29="","",IF($I29=0,"SIN ROTACIÓN",IF($E29="","",IF($E29="Numerada",IF($Q29<8,"CRÍTICO",IF($Q29<15,"ALERTA","OK")),IF($Q29<=90,"CRÍTICO",IF($Q29<=150,"ALERTA","OK")))))) | S29: =IF(OR($C29="",$E29="",$I29=0),"",IF($E29="Numerada",IF(AND($O29<8,$Q29>=8),"PRODUCIR - "&TEXT($O29,"0")&" d terminado",""),IF(AND($O29<=90,$Q29>90),"PRODUCIR - "&TEXT($O29,"0")&" d terminado","")))
A30: MOVISTAR.HALFSIM | B30: 14 | C30: 1621412 | D30: HALFSIM MOVISTAR LINEA NUEVA | E30: Blanca | F30: =SUMIFS('DESPACHOS 20 DIAS'!F:F,'DESPACHOS 20 DIAS'!D:D,$C30,'DESPACHOS 20 DIAS'!E:E,$D30,'DESPACHOS 20 DIAS'!N:N,"CANAL INDIRECTO") | G30: =SUMIFS('DESPACHOS 20 DIAS'!F:F,'DESPACHOS 20 DIAS'!D:D,$C30,'DESPACHOS 20 DIAS'!E:E,$D30,'DESPACHOS 20 DIAS'!N:N,"CANAL DIRECTO") | H30: =F30+G30 | I30: =IFERROR(H30/DIAS_PERIODO,0) | J30: 0 | K30: =SUMIFS(INVENTARIO!E:E,INVENTARIO!D:D,$C30,INVENTARIO!B:B,$D30,INVENTARIO!A:A,"PRODUCCION") | L30: =SUMIFS(INVENTARIO!E:E,INVENTARIO!D:D,$C30,INVENTARIO!B:B,$D30,INVENTARIO!A:A,"MATERIA PRIMA") | M30: =IF($I30=0,"",L30/$I30) | N30: =SUMIFS(INVENTARIO!E:E,INVENTARIO!D:D,$C30,INVENTARIO!B:B,$D30,INVENTARIO!A:A,"BODEGA CENTRAL")+SUMIFS(INVENTARIO!E:E,INVENTARIO!D:D,$C30,INVENTARIO!B:B,$D30,INVENTARIO!A:A,"DELIVERY") | O30: =IF($I30=0,"",N30/$I30) | P30: =L30+N30+K30 | Q30: =IF($I30=0,"",P30/$I30) | R30: =IF($D30="","",IF($I30=0,"SIN ROTACIÓN",IF($E30="","",IF($E30="Numerada",IF($Q30<8,"CRÍTICO",IF($Q30<15,"ALERTA","OK")),IF($Q30<=90,"CRÍTICO",IF($Q30<=150,"ALERTA","OK")))))) | S30: =IF(OR($C30="",$E30="",$I30=0),"",IF($E30="Numerada",IF(AND($O30<8,$Q30>=8),"PRODUCIR - "&TEXT($O30,"0")&" d terminado",""),IF(AND($O30<=90,$Q30>90),"PRODUCIR - "&TEXT($O30,"0")&" d terminado","")))
D31: Subtotal HALFSIM MOVISTAR (FÍSICA) | E31: Blanca | F31: =SUMIFS(F$13:F$73,$A$13:$A$73,"MOVISTAR.HALFSIM") | G31: =SUMIFS(G$13:G$73,$A$13:$A$73,"MOVISTAR.HALFSIM") | H31: =SUMIFS(H$13:H$73,$A$13:$A$73,"MOVISTAR.HALFSIM") | I31: =IFERROR(H31/DIAS_PERIODO,0) | J31: =SUMIFS(J$13:J$73,$A$13:$A$73,"MOVISTAR.HALFSIM") | K31: =SUMIFS(K$13:K$73,$A$13:$A$73,"MOVISTAR.HALFSIM") | L31: =SUMIFS(L$13:L$73,$A$13:$A$73,"MOVISTAR.HALFSIM") | M31: =IF($I31=0,"",L31/$I31) | N31: =SUMIFS(N$13:N$73,$A$13:$A$73,"MOVISTAR.HALFSIM") | O31: =IF($I31=0,"",N31/$I31) | P31: =SUMIFS(P$13:P$73,$A$13:$A$73,"MOVISTAR.HALFSIM") | Q31: =IF($I31=0,"",P31/$I31) | R31: =IF($D31="","",IF($I31=0,"SIN ROTACIÓN",IF($E31="","",IF($E31="Numerada",IF($Q31<8,"CRÍTICO",IF($Q31<15,"ALERTA","OK")),IF($Q31<=90,"CRÍTICO",IF($Q31<=150,"ALERTA","OK")))))) | S31: =IF(OR($C31="",$E31="",$I31=0),"",IF($E31="Numerada",IF(AND($O31<8,$Q31>=8),"PRODUCIR - "&TEXT($O31,"0")&" d terminado",""),IF(AND($O31<=90,$Q31>90),"PRODUCIR - "&TEXT($O31,"0")&" d terminado","")))
A32: MOVISTAR.ESIM | B32: 15 | C32: 162119 | D32: ESIM MOVISTAR | E32: Blanca | F32: =SUMIFS('DESPACHOS 20 DIAS'!F:F,'DESPACHOS 20 DIAS'!D:D,$C32,'DESPACHOS 20 DIAS'!E:E,$D32,'DESPACHOS 20 DIAS'!N:N,"CANAL INDIRECTO") | G32: =SUMIFS('DESPACHOS 20 DIAS'!F:F,'DESPACHOS 20 DIAS'!D:D,$C32,'DESPACHOS 20 DIAS'!E:E,$D32,'DESPACHOS 20 DIAS'!N:N,"CANAL DIRECTO") | H32: =F32+G32 | I32: =IFERROR(H32/DIAS_PERIODO,0) | J32: 0 | K32: =SUMIFS(INVENTARIO!E:E,INVENTARIO!D:D,$C32,INVENTARIO!B:B,$D32,INVENTARIO!A:A,"PRODUCCION") | L32: =SUMIFS(INVENTARIO!E:E,INVENTARIO!D:D,$C32,INVENTARIO!B:B,$D32,INVENTARIO!A:A,"MATERIA PRIMA") | M32: =IF($I32=0,"",L32/$I32) | N32: =SUMIFS(INVENTARIO!E:E,INVENTARIO!D:D,$C32,INVENTARIO!B:B,$D32,INVENTARIO!A:A,"BODEGA CENTRAL")+SUMIFS(INVENTARIO!E:E,INVENTARIO!D:D,$C32,INVENTARIO!B:B,$D32,INVENTARIO!A:A,"DELIVERY") | O32: =IF($I32=0,"",N32/$I32) | P32: =L32+N32+K32 | Q32: =IF($I32=0,"",P32/$I32) | R32: =IF($D32="","",IF($I32=0,"SIN ROTACIÓN",IF($E32="","",IF($E32="Numerada",IF($Q32<8,"CRÍTICO",IF($Q32<15,"ALERTA","OK")),IF($Q32<=90,"CRÍTICO",IF($Q32<=150,"ALERTA","OK")))))) | S32: =IF(OR($C32="",$E32="",$I32=0),"",IF($E32="Numerada",IF(AND($O32<8,$Q32>=8),"PRODUCIR - "&TEXT($O32,"0")&" d terminado",""),IF(AND($O32<=90,$Q32>90),"PRODUCIR - "&TEXT($O32,"0")&" d terminado","")))
A33: MOVISTAR.ESIM | B33: 16 | C33: 162956 | D33: ESIM MOVISTAR DIGITAL | E33: Blanca | F33: =SUMIFS('DESPACHOS 20 DIAS'!F:F,'DESPACHOS 20 DIAS'!D:D,$C33,'DESPACHOS 20 DIAS'!E:E,$D33,'DESPACHOS 20 DIAS'!N:N,"CANAL INDIRECTO") | G33: =SUMIFS('DESPACHOS 20 DIAS'!F:F,'DESPACHOS 20 DIAS'!D:D,$C33,'DESPACHOS 20 DIAS'!E:E,$D33,'DESPACHOS 20 DIAS'!N:N,"CANAL DIRECTO") | H33: =F33+G33 | I33: =IFERROR(H33/DIAS_PERIODO,0) | J33: 0 | K33: =SUMIFS(INVENTARIO!E:E,INVENTARIO!D:D,$C33,INVENTARIO!B:B,$D33,INVENTARIO!A:A,"PRODUCCION") | L33: =SUMIFS(INVENTARIO!E:E,INVENTARIO!D:D,$C33,INVENTARIO!B:B,$D33,INVENTARIO!A:A,"MATERIA PRIMA") | M33: =IF($I33=0,"",L33/$I33) | N33: =SUMIFS(INVENTARIO!E:E,INVENTARIO!D:D,$C33,INVENTARIO!B:B,$D33,INVENTARIO!A:A,"BODEGA CENTRAL")+SUMIFS(INVENTARIO!E:E,INVENTARIO!D:D,$C33,INVENTARIO!B:B,$D33,INVENTARIO!A:A,"DELIVERY") | O33: =IF($I33=0,"",N33/$I33) | P33: =L33+N33+K33 | Q33: =IF($I33=0,"",P33/$I33) | R33: =IF($D33="","",IF($I33=0,"SIN ROTACIÓN",IF($E33="","",IF($E33="Numerada",IF($Q33<8,"CRÍTICO",IF($Q33<15,"ALERTA","OK")),IF($Q33<=90,"CRÍTICO",IF($Q33<=150,"ALERTA","OK")))))) | S33: =IF(OR($C33="",$E33="",$I33=0),"",IF($E33="Numerada",IF(AND($O33<8,$Q33>=8),"PRODUCIR - "&TEXT($O33,"0")&" d terminado",""),IF(AND($O33<=90,$Q33>90),"PRODUCIR - "&TEXT($O33,"0")&" d terminado","")))
D34: Subtotal ESIM MOVISTAR (DIGITAL) | E34: Blanca | F34: =SUMIFS(F$13:F$73,$A$13:$A$73,"MOVISTAR.ESIM") | G34: =SUMIFS(G$13:G$73,$A$13:$A$73,"MOVISTAR.ESIM") | H34: =SUMIFS(H$13:H$73,$A$13:$A$73,"MOVISTAR.ESIM") | I34: =IFERROR(H34/DIAS_PERIODO,0) | J34: =SUMIFS(J$13:J$73,$A$13:$A$73,"MOVISTAR.ESIM") | K34: =SUMIFS(K$13:K$73,$A$13:$A$73,"MOVISTAR.ESIM") | L34: =SUMIFS(L$13:L$73,$A$13:$A$73,"MOVISTAR.ESIM") | M34: =IF($I34=0,"",L34/$I34) | N34: =SUMIFS(N$13:N$73,$A$13:$A$73,"MOVISTAR.ESIM") | O34: =IF($I34=0,"",N34/$I34) | P34: =SUMIFS(P$13:P$73,$A$13:$A$73,"MOVISTAR.ESIM") | Q34: =IF($I34=0,"",P34/$I34) | R34: =IF($D34="","",IF($I34=0,"SIN ROTACIÓN",IF($E34="","",IF($E34="Numerada",IF($Q34<8,"CRÍTICO",IF($Q34<15,"ALERTA","OK")),IF($Q34<=90,"CRÍTICO",IF($Q34<=150,"ALERTA","OK")))))) | S34: =IF(OR($C34="",$E34="",$I34=0),"",IF($E34="Numerada",IF(AND($O34<8,$Q34>=8),"PRODUCIR - "&TEXT($O34,"0")&" d terminado",""),IF(AND($O34<=90,$Q34>90),"PRODUCIR - "&TEXT($O34,"0")&" d terminado","")))
D35: TOTAL MOVISTAR | E35: Blanca | F35: =SUMIFS(F$13:F$73,$A$13:$A$73,"MOVISTAR.*") | G35: =SUMIFS(G$13:G$73,$A$13:$A$73,"MOVISTAR.*") | H35: =SUMIFS(H$13:H$73,$A$13:$A$73,"MOVISTAR.*") | I35: =IFERROR(H35/DIAS_PERIODO,0) | J35: =SUMIFS(J$13:J$73,$A$13:$A$73,"MOVISTAR.*") | K35: =SUMIFS(K$13:K$73,$A$13:$A$73,"MOVISTAR.*") | L35: =SUMIFS(L$13:L$73,$A$13:$A$73,"MOVISTAR.*") | M35: =IF($I35=0,"",L35/$I35) | N35: =SUMIFS(N$13:N$73,$A$13:$A$73,"MOVISTAR.*") | O35: =IF($I35=0,"",N35/$I35) | P35: =SUMIFS(P$13:P$73,$A$13:$A$73,"MOVISTAR.*") | Q35: =IF($I35=0,"",P35/$I35) | R35: =IF($D35="","",IF($I35=0,"SIN ROTACIÓN",IF($E35="","",IF($E35="Numerada",IF($Q35<8,"CRÍTICO",IF($Q35<15,"ALERTA","OK")),IF($Q35<=90,"CRÍTICO",IF($Q35<=150,"ALERTA","OK")))))) | S35: =IF(OR($C35="",$E35="",$I35=0),"",IF($E35="Numerada",IF(AND($O35<8,$Q35>=8),"PRODUCIR - "&TEXT($O35,"0")&" d terminado",""),IF(AND($O35<=90,$Q35>90),"PRODUCIR - "&TEXT($O35,"0")&" d terminado","")))
A36: TIGO.HALFSIM | B36: 17 | C36: 163140 | D36: HALFSIM TIGO | E36: Blanca | F36: =SUMIFS('DESPACHOS 20 DIAS'!F:F,'DESPACHOS 20 DIAS'!D:D,$C36,'DESPACHOS 20 DIAS'!E:E,$D36,'DESPACHOS 20 DIAS'!N:N,"CANAL INDIRECTO") | G36: =SUMIFS('DESPACHOS 20 DIAS'!F:F,'DESPACHOS 20 DIAS'!D:D,$C36,'DESPACHOS 20 DIAS'!E:E,$D36,'DESPACHOS 20 DIAS'!N:N,"CANAL DIRECTO") | H36: =F36+G36 | I36: =IFERROR(H36/DIAS_PERIODO,0) | J36: 0 | K36: =SUMIFS(INVENTARIO!E:E,INVENTARIO!D:D,$C36,INVENTARIO!B:B,$D36,INVENTARIO!A:A,"PRODUCCION") | L36: =SUMIFS(INVENTARIO!E:E,INVENTARIO!D:D,$C36,INVENTARIO!B:B,$D36,INVENTARIO!A:A,"MATERIA PRIMA") | M36: =IF($I36=0,"",L36/$I36) | N36: =SUMIFS(INVENTARIO!E:E,INVENTARIO!D:D,$C36,INVENTARIO!B:B,$D36,INVENTARIO!A:A,"BODEGA CENTRAL")+SUMIFS(INVENTARIO!E:E,INVENTARIO!D:D,$C36,INVENTARIO!B:B,$D36,INVENTARIO!A:A,"DELIVERY") | O36: =IF($I36=0,"",N36/$I36) | P36: =L36+N36+K36 | Q36: =IF($I36=0,"",P36/$I36) | R36: =IF($D36="","",IF($I36=0,"SIN ROTACIÓN",IF($E36="","",IF($E36="Numerada",IF($Q36<8,"CRÍTICO",IF($Q36<15,"ALERTA","OK")),IF($Q36<=90,"CRÍTICO",IF($Q36<=150,"ALERTA","OK")))))) | S36: =IF(OR($C36="",$E36="",$I36=0),"",IF($E36="Numerada",IF(AND($O36<8,$Q36>=8),"PRODUCIR - "&TEXT($O36,"0")&" d terminado",""),IF(AND($O36<=90,$Q36>90),"PRODUCIR - "&TEXT($O36,"0")&" d terminado","")))
A37: TIGO.HALFSIM | B37: 18 | C37: 163140 | D37: HALFSIM TIGO PORTABILIDAD | E37: Blanca | F37: =SUMIFS('DESPACHOS 20 DIAS'!F:F,'DESPACHOS 20 DIAS'!D:D,$C37,'DESPACHOS 20 DIAS'!E:E,$D37,'DESPACHOS 20 DIAS'!N:N,"CANAL INDIRECTO") | G37: =SUMIFS('DESPACHOS 20 DIAS'!F:F,'DESPACHOS 20 DIAS'!D:D,$C37,'DESPACHOS 20 DIAS'!E:E,$D37,'DESPACHOS 20 DIAS'!N:N,"CANAL DIRECTO") | H37: =F37+G37 | I37: =IFERROR(H37/DIAS_PERIODO,0) | J37: 0 | K37: =SUMIFS(INVENTARIO!E:E,INVENTARIO!D:D,$C37,INVENTARIO!B:B,$D37,INVENTARIO!A:A,"PRODUCCION") | L37: =SUMIFS(INVENTARIO!E:E,INVENTARIO!D:D,$C37,INVENTARIO!B:B,$D37,INVENTARIO!A:A,"MATERIA PRIMA") | M37: =IF($I37=0,"",L37/$I37) | N37: =SUMIFS(INVENTARIO!E:E,INVENTARIO!D:D,$C37,INVENTARIO!B:B,$D37,INVENTARIO!A:A,"BODEGA CENTRAL")+SUMIFS(INVENTARIO!E:E,INVENTARIO!D:D,$C37,INVENTARIO!B:B,$D37,INVENTARIO!A:A,"DELIVERY") | O37: =IF($I37=0,"",N37/$I37) | P37: =L37+N37+K37 | Q37: =IF($I37=0,"",P37/$I37) | R37: =IF($D37="","",IF($I37=0,"SIN ROTACIÓN",IF($E37="","",IF($E37="Numerada",IF($Q37<8,"CRÍTICO",IF($Q37<15,"ALERTA","OK")),IF($Q37<=90,"CRÍTICO",IF($Q37<=150,"ALERTA","OK")))))) | S37: =IF(OR($C37="",$E37="",$I37=0),"",IF($E37="Numerada",IF(AND($O37<8,$Q37>=8),"PRODUCIR - "&TEXT($O37,"0")&" d terminado",""),IF(AND($O37<=90,$Q37>90),"PRODUCIR - "&TEXT($O37,"0")&" d terminado","")))
A38: TIGO.HALFSIM | B38: 19 | C38: 163140 | D38: HALFSIM TIGO REPOSICIÓN | E38: Blanca | F38: =SUMIFS('DESPACHOS 20 DIAS'!F:F,'DESPACHOS 20 DIAS'!D:D,$C38,'DESPACHOS 20 DIAS'!E:E,$D38,'DESPACHOS 20 DIAS'!N:N,"CANAL INDIRECTO") | G38: =SUMIFS('DESPACHOS 20 DIAS'!F:F,'DESPACHOS 20 DIAS'!D:D,$C38,'DESPACHOS 20 DIAS'!E:E,$D38,'DESPACHOS 20 DIAS'!N:N,"CANAL DIRECTO") | H38: =F38+G38 | I38: =IFERROR(H38/DIAS_PERIODO,0) | J38: 0 | K38: =SUMIFS(INVENTARIO!E:E,INVENTARIO!D:D,$C38,INVENTARIO!B:B,$D38,INVENTARIO!A:A,"PRODUCCION") | L38: =SUMIFS(INVENTARIO!E:E,INVENTARIO!D:D,$C38,INVENTARIO!B:B,$D38,INVENTARIO!A:A,"MATERIA PRIMA") | M38: =IF($I38=0,"",L38/$I38) | N38: =SUMIFS(INVENTARIO!E:E,INVENTARIO!D:D,$C38,INVENTARIO!B:B,$D38,INVENTARIO!A:A,"BODEGA CENTRAL")+SUMIFS(INVENTARIO!E:E,INVENTARIO!D:D,$C38,INVENTARIO!B:B,$D38,INVENTARIO!A:A,"DELIVERY") | O38: =IF($I38=0,"",N38/$I38) | P38: =L38+N38+K38 | Q38: =IF($I38=0,"",P38/$I38) | R38: =IF($D38="","",IF($I38=0,"SIN ROTACIÓN",IF($E38="","",IF($E38="Numerada",IF($Q38<8,"CRÍTICO",IF($Q38<15,"ALERTA","OK")),IF($Q38<=90,"CRÍTICO",IF($Q38<=150,"ALERTA","OK")))))) | S38: =IF(OR($C38="",$E38="",$I38=0),"",IF($E38="Numerada",IF(AND($O38<8,$Q38>=8),"PRODUCIR - "&TEXT($O38,"0")&" d terminado",""),IF(AND($O38<=90,$Q38>90),"PRODUCIR - "&TEXT($O38,"0")&" d terminado","")))
D39: Subtotal HALFSIM TIGO (COMERCIAL) | E39: Blanca | F39: =SUMIFS(F$13:F$73,$A$13:$A$73,"TIGO.HALFSIM") | G39: =SUMIFS(G$13:G$73,$A$13:$A$73,"TIGO.HALFSIM") | H39: =SUMIFS(H$13:H$73,$A$13:$A$73,"TIGO.HALFSIM") | I39: =IFERROR(H39/DIAS_PERIODO,0) | J39: =SUMIFS(J$13:J$73,$A$13:$A$73,"TIGO.HALFSIM") | K39: =SUMIFS(K$13:K$73,$A$13:$A$73,"TIGO.HALFSIM") | L39: =SUMIFS(L$13:L$73,$A$13:$A$73,"TIGO.HALFSIM") | M39: =IF($I39=0,"",L39/$I39) | N39: =SUMIFS(N$13:N$73,$A$13:$A$73,"TIGO.HALFSIM") | O39: =IF($I39=0,"",N39/$I39) | P39: =SUMIFS(P$13:P$73,$A$13:$A$73,"TIGO.HALFSIM") | Q39: =IF($I39=0,"",P39/$I39) | R39: =IF($D39="","",IF($I39=0,"SIN ROTACIÓN",IF($E39="","",IF($E39="Numerada",IF($Q39<8,"CRÍTICO",IF($Q39<15,"ALERTA","OK")),IF($Q39<=90,"CRÍTICO",IF($Q39<=150,"ALERTA","OK")))))) | S39: =IF(OR($C39="",$E39="",$I39=0),"",IF($E39="Numerada",IF(AND($O39<8,$Q39>=8),"PRODUCIR - "&TEXT($O39,"0")&" d terminado",""),IF(AND($O39<=90,$Q39>90),"PRODUCIR - "&TEXT($O39,"0")&" d terminado","")))
A40: TIGO.CHIP3 | B40: 20 | C40: 163140 | D40: HALFSIM TIGO CHIP PREPAGO $3 WP AUTOSERVICIO NUMERADO | E40: Numerada | F40: =SUMIFS('DESPACHOS 20 DIAS'!F:F,'DESPACHOS 20 DIAS'!D:D,$C40,'DESPACHOS 20 DIAS'!E:E,$D40,'DESPACHOS 20 DIAS'!N:N,"CANAL INDIRECTO") | G40: =SUMIFS('DESPACHOS 20 DIAS'!F:F,'DESPACHOS 20 DIAS'!D:D,$C40,'DESPACHOS 20 DIAS'!E:E,$D40,'DESPACHOS 20 DIAS'!N:N,"CANAL DIRECTO") | H40: =F40+G40 | I40: =IFERROR(H40/DIAS_PERIODO,0) | J40: 0 | K40: =SUMIFS(INVENTARIO!E:E,INVENTARIO!D:D,$C40,INVENTARIO!B:B,$D40,INVENTARIO!A:A,"PRODUCCION") | L40: =SUMIFS(INVENTARIO!E:E,INVENTARIO!D:D,$C40,INVENTARIO!B:B,$D40,INVENTARIO!A:A,"MATERIA PRIMA") | M40: =IF($I40=0,"",L40/$I40) | N40: =SUMIFS(INVENTARIO!E:E,INVENTARIO!D:D,$C40,INVENTARIO!B:B,$D40,INVENTARIO!A:A,"BODEGA CENTRAL")+SUMIFS(INVENTARIO!E:E,INVENTARIO!D:D,$C40,INVENTARIO!B:B,$D40,INVENTARIO!A:A,"DELIVERY") | O40: =IF($I40=0,"",N40/$I40) | P40: =L40+N40+K40 | Q40: =IF($I40=0,"",P40/$I40) | R40: =IF($D40="","",IF($I40=0,"SIN ROTACIÓN",IF($E40="","",IF($E40="Numerada",IF($Q40<8,"CRÍTICO",IF($Q40<15,"ALERTA","OK")),IF($Q40<=90,"CRÍTICO",IF($Q40<=150,"ALERTA","OK")))))) | S40: =IF(OR($C40="",$E40="",$I40=0),"",IF($E40="Numerada",IF(AND($O40<8,$Q40>=8),"PRODUCIR - "&TEXT($O40,"0")&" d terminado",""),IF(AND($O40<=90,$Q40>90),"PRODUCIR - "&TEXT($O40,"0")&" d terminado","")))
A41: TIGO.CHIP3 | B41: 21 | C41: 163140 | D41: HALFSIM TIGO CHIP PREPAGO $3 WP CANAL DIRECTO NUMERADO | E41: Numerada | F41: =SUMIFS('DESPACHOS 20 DIAS'!F:F,'DESPACHOS 20 DIAS'!D:D,$C41,'DESPACHOS 20 DIAS'!E:E,$D41,'DESPACHOS 20 DIAS'!N:N,"CANAL INDIRECTO") | G41: =SUMIFS('DESPACHOS 20 DIAS'!F:F,'DESPACHOS 20 DIAS'!D:D,$C41,'DESPACHOS 20 DIAS'!E:E,$D41,'DESPACHOS 20 DIAS'!N:N,"CANAL DIRECTO") | H41: =F41+G41 | I41: =IFERROR(H41/DIAS_PERIODO,0) | J41: 0 | K41: =SUMIFS(INVENTARIO!E:E,INVENTARIO!D:D,$C41,INVENTARIO!B:B,$D41,INVENTARIO!A:A,"PRODUCCION") | L41: =SUMIFS(INVENTARIO!E:E,INVENTARIO!D:D,$C41,INVENTARIO!B:B,$D41,INVENTARIO!A:A,"MATERIA PRIMA") | M41: =IF($I41=0,"",L41/$I41) | N41: =SUMIFS(INVENTARIO!E:E,INVENTARIO!D:D,$C41,INVENTARIO!B:B,$D41,INVENTARIO!A:A,"BODEGA CENTRAL")+SUMIFS(INVENTARIO!E:E,INVENTARIO!D:D,$C41,INVENTARIO!B:B,$D41,INVENTARIO!A:A,"DELIVERY") | O41: =IF($I41=0,"",N41/$I41) | P41: =L41+N41+K41 | Q41: =IF($I41=0,"",P41/$I41) | R41: =IF($D41="","",IF($I41=0,"SIN ROTACIÓN",IF($E41="","",IF($E41="Numerada",IF($Q41<8,"CRÍTICO",IF($Q41<15,"ALERTA","OK")),IF($Q41<=90,"CRÍTICO",IF($Q41<=150,"ALERTA","OK")))))) | S41: =IF(OR($C41="",$E41="",$I41=0),"",IF($E41="Numerada",IF(AND($O41<8,$Q41>=8),"PRODUCIR - "&TEXT($O41,"0")&" d terminado",""),IF(AND($O41<=90,$Q41>90),"PRODUCIR - "&TEXT($O41,"0")&" d terminado","")))
A42: TIGO.CHIP3 | B42: 22 | C42: 163140 | D42: HALFSIM TIGO CHIP PREPAGO $3 WP DUOCELL NUMERADO | E42: Numerada | F42: =SUMIFS('DESPACHOS 20 DIAS'!F:F,'DESPACHOS 20 DIAS'!D:D,$C42,'DESPACHOS 20 DIAS'!E:E,$D42,'DESPACHOS 20 DIAS'!N:N,"CANAL INDIRECTO") | G42: =SUMIFS('DESPACHOS 20 DIAS'!F:F,'DESPACHOS 20 DIAS'!D:D,$C42,'DESPACHOS 20 DIAS'!E:E,$D42,'DESPACHOS 20 DIAS'!N:N,"CANAL DIRECTO") | H42: =F42+G42 | I42: =IFERROR(H42/DIAS_PERIODO,0) | J42: 0 | K42: =SUMIFS(INVENTARIO!E:E,INVENTARIO!D:D,$C42,INVENTARIO!B:B,$D42,INVENTARIO!A:A,"PRODUCCION") | L42: =SUMIFS(INVENTARIO!E:E,INVENTARIO!D:D,$C42,INVENTARIO!B:B,$D42,INVENTARIO!A:A,"MATERIA PRIMA") | M42: =IF($I42=0,"",L42/$I42) | N42: =SUMIFS(INVENTARIO!E:E,INVENTARIO!D:D,$C42,INVENTARIO!B:B,$D42,INVENTARIO!A:A,"BODEGA CENTRAL")+SUMIFS(INVENTARIO!E:E,INVENTARIO!D:D,$C42,INVENTARIO!B:B,$D42,INVENTARIO!A:A,"DELIVERY") | O42: =IF($I42=0,"",N42/$I42) | P42: =L42+N42+K42 | Q42: =IF($I42=0,"",P42/$I42) | R42: =IF($D42="","",IF($I42=0,"SIN ROTACIÓN",IF($E42="","",IF($E42="Numerada",IF($Q42<8,"CRÍTICO",IF($Q42<15,"ALERTA","OK")),IF($Q42<=90,"CRÍTICO",IF($Q42<=150,"ALERTA","OK")))))) | S42: =IF(OR($C42="",$E42="",$I42=0),"",IF($E42="Numerada",IF(AND($O42<8,$Q42>=8),"PRODUCIR - "&TEXT($O42,"0")&" d terminado",""),IF(AND($O42<=90,$Q42>90),"PRODUCIR - "&TEXT($O42,"0")&" d terminado","")))
A43: TIGO.CHIP3 | B43: 23 | C43: 163140 | D43: HALFSIM TIGO CHIP PREPAGO $3 WP NUMERADO | E43: Numerada | F43: =SUMIFS('DESPACHOS 20 DIAS'!F:F,'DESPACHOS 20 DIAS'!D:D,$C43,'DESPACHOS 20 DIAS'!E:E,$D43,'DESPACHOS 20 DIAS'!N:N,"CANAL INDIRECTO") | G43: =SUMIFS('DESPACHOS 20 DIAS'!F:F,'DESPACHOS 20 DIAS'!D:D,$C43,'DESPACHOS 20 DIAS'!E:E,$D43,'DESPACHOS 20 DIAS'!N:N,"CANAL DIRECTO") | H43: =F43+G43 | I43: =IFERROR(H43/DIAS_PERIODO,0) | J43: 0 | K43: =SUMIFS(INVENTARIO!E:E,INVENTARIO!D:D,$C43,INVENTARIO!B:B,$D43,INVENTARIO!A:A,"PRODUCCION") | L43: =SUMIFS(INVENTARIO!E:E,INVENTARIO!D:D,$C43,INVENTARIO!B:B,$D43,INVENTARIO!A:A,"MATERIA PRIMA") | M43: =IF($I43=0,"",L43/$I43) | N43: =SUMIFS(INVENTARIO!E:E,INVENTARIO!D:D,$C43,INVENTARIO!B:B,$D43,INVENTARIO!A:A,"BODEGA CENTRAL")+SUMIFS(INVENTARIO!E:E,INVENTARIO!D:D,$C43,INVENTARIO!B:B,$D43,INVENTARIO!A:A,"DELIVERY") | O43: =IF($I43=0,"",N43/$I43) | P43: =L43+N43+K43 | Q43: =IF($I43=0,"",P43/$I43) | R43: =IF($D43="","",IF($I43=0,"SIN ROTACIÓN",IF($E43="","",IF($E43="Numerada",IF($Q43<8,"CRÍTICO",IF($Q43<15,"ALERTA","OK")),IF($Q43<=90,"CRÍTICO",IF($Q43<=150,"ALERTA","OK")))))) | S43: =IF(OR($C43="",$E43="",$I43=0),"",IF($E43="Numerada",IF(AND($O43<8,$Q43>=8),"PRODUCIR - "&TEXT($O43,"0")&" d terminado",""),IF(AND($O43<=90,$Q43>90),"PRODUCIR - "&TEXT($O43,"0")&" d terminado","")))
D44: Subtotal HALFSIM TIGO CHIP PREPAGO $3 (NUMERADA) | E44: Numerada | F44: =SUMIFS(F$13:F$73,$A$13:$A$73,"TIGO.CHIP3") | G44: =SUMIFS(G$13:G$73,$A$13:$A$73,"TIGO.CHIP3") | H44: =SUMIFS(H$13:H$73,$A$13:$A$73,"TIGO.CHIP3") | I44: =IFERROR(H44/DIAS_PERIODO,0) | J44: =SUMIFS(J$13:J$73,$A$13:$A$73,"TIGO.CHIP3") | K44: =SUMIFS(K$13:K$73,$A$13:$A$73,"TIGO.CHIP3") | L44: =SUMIFS(L$13:L$73,$A$13:$A$73,"TIGO.CHIP3") | M44: =IF($I44=0,"",L44/$I44) | N44: =SUMIFS(N$13:N$73,$A$13:$A$73,"TIGO.CHIP3") | O44: =IF($I44=0,"",N44/$I44) | P44: =SUMIFS(P$13:P$73,$A$13:$A$73,"TIGO.CHIP3") | Q44: =IF($I44=0,"",P44/$I44) | R44: =IF($D44="","",IF($I44=0,"SIN ROTACIÓN",IF($E44="","",IF($E44="Numerada",IF($Q44<8,"CRÍTICO",IF($Q44<15,"ALERTA","OK")),IF($Q44<=90,"CRÍTICO",IF($Q44<=150,"ALERTA","OK")))))) | S44: =IF(OR($C44="",$E44="",$I44=0),"",IF($E44="Numerada",IF(AND($O44<8,$Q44>=8),"PRODUCIR - "&TEXT($O44,"0")&" d terminado",""),IF(AND($O44<=90,$Q44>90),"PRODUCIR - "&TEXT($O44,"0")&" d terminado","")))
A45: TIGO.ESIM | B45: 24 | C45: 163141 | D45: ESIM TIGO DIGITAL | E45: Blanca | F45: =SUMIFS('DESPACHOS 20 DIAS'!F:F,'DESPACHOS 20 DIAS'!D:D,$C45,'DESPACHOS 20 DIAS'!E:E,$D45,'DESPACHOS 20 DIAS'!N:N,"CANAL INDIRECTO") | G45: =SUMIFS('DESPACHOS 20 DIAS'!F:F,'DESPACHOS 20 DIAS'!D:D,$C45,'DESPACHOS 20 DIAS'!E:E,$D45,'DESPACHOS 20 DIAS'!N:N,"CANAL DIRECTO") | H45: =F45+G45 | I45: =IFERROR(H45/DIAS_PERIODO,0) | J45: 0 | K45: =SUMIFS(INVENTARIO!E:E,INVENTARIO!D:D,$C45,INVENTARIO!B:B,$D45,INVENTARIO!A:A,"PRODUCCION") | L45: =SUMIFS(INVENTARIO!E:E,INVENTARIO!D:D,$C45,INVENTARIO!B:B,$D45,INVENTARIO!A:A,"MATERIA PRIMA") | M45: =IF($I45=0,"",L45/$I45) | N45: =SUMIFS(INVENTARIO!E:E,INVENTARIO!D:D,$C45,INVENTARIO!B:B,$D45,INVENTARIO!A:A,"BODEGA CENTRAL")+SUMIFS(INVENTARIO!E:E,INVENTARIO!D:D,$C45,INVENTARIO!B:B,$D45,INVENTARIO!A:A,"DELIVERY") | O45: =IF($I45=0,"",N45/$I45) | P45: =L45+N45+K45 | Q45: =IF($I45=0,"",P45/$I45) | R45: =IF($D45="","",IF($I45=0,"SIN ROTACIÓN",IF($E45="","",IF($E45="Numerada",IF($Q45<8,"CRÍTICO",IF($Q45<15,"ALERTA","OK")),IF($Q45<=90,"CRÍTICO",IF($Q45<=150,"ALERTA","OK")))))) | S45: =IF(OR($C45="",$E45="",$I45=0),"",IF($E45="Numerada",IF(AND($O45<8,$Q45>=8),"PRODUCIR - "&TEXT($O45,"0")&" d terminado",""),IF(AND($O45<=90,$Q45>90),"PRODUCIR - "&TEXT($O45,"0")&" d terminado","")))
...

Sheet PMP
A1: Artículo | B1: Descripcion Articulo | C1: Artículo | H1: PIA | I1: JANUS
A2: 1 | B2: SIMCARD 2FF PREPAGO | C2: 1 | H2: 1598 | I2: 82944 | J2: =+VLOOKUP(I2,A:B,2,0)
A3: 2 | B3: SIMCARD 2FF POSTPAGO | C3: 2 | H3: 1599 | I3: 81944 | J3: =+VLOOKUP(I3,A:B,2,0)
A4: 3 | B4: GSM ALCATEL 155 | C4: 3 | H4: 1600 | I4: 105944 | J4: =+VLOOKUP(I4,A:B,2,0)
A5: 4 | B5: GSM ALCATEL 156a | C5: 4 | H5: 1601 | I5: 81944 | J5: =+VLOOKUP(I5,A:B,2,0)
A6: 5 | B6: GSM MOTOROLA V172 | C6: 5 | H6: 1603 | I6: 82944 | J6: =+VLOOKUP(I6,A:B,2,0)
A7: 6 | B7: GSM MOTOROLA C116 | C7: 6 | H7: 1604 | I7: 81944 | J7: =+VLOOKUP(I7,A:B,2,0)
A8: 7 | B8: GSM MOTOROLA C155 | C8: 7 | H8: 1606 | I8: 105944 | J8: =+VLOOKUP(I8,A:B,2,0)
A9: 8 | B9: GSM MOTOROLA C650 | C9: 8 | H9: 1640 | I9: 105944 | J9: =+VLOOKUP(I9,A:B,2,0)
A10: 10 | B10: GSM MOVISTAR 340 | C10: 10 | H10: 1648 | I10: 84948 | J10: =+VLOOKUP(I10,A:B,2,0)
A11: 11 | B11: TARJETA PREPAGO US$3 | C11: 11 | H11: 1649 | I11: 84948 | J11: =+VLOOKUP(I11,A:B,2,0)
A12: 12 | B12: GSM NOKIA 2600 | C12: 12 | H12: 1651 | I12: 84948 | J12: =+VLOOKUP(I12,A:B,2,0)
A13: 13 | B13: GSM NOKIA 2651 | C13: 13 | H13: 1652 | I13: 113950 | J13: =+VLOOKUP(I13,A:B,2,0)
... A29: 34 | B29: LISTO PACK GSM NOKIA 3200 | C29: 34 | H29: 1674 | I29: 96946 | J29: =+VLOOKUP(I29,A:B,2,0)
A30: 35 | B30: LISTO PACK GSM NOKIA 3220 | C30: 35 | H30: 2324 | I30: #N/A | J30: =+VLOOKUP(I30,A:B,2,0)
A31: 51 | B31: LISTO PACK GSM SIEMENS C66 | C31: 51 | H31: 1337 | I31: 1534 | J31: =+VLOOKUP(I31,A:B,2,0)
A32: 52 | B32: GSM NOKIA 1108 | C32: 52 | H32: 1398 | I32: 1534 | J32: =+VLOOKUP(I32,A:B,2,0)
A33: 53 | B33: GSM MOVISTAR 110 | C33: 53 | H33: 1399 | I33: 1534 | J33: =+VLOOKUP(I33,A:B,2,0)
A34: 54 | B34: LISTO PACK GSM NOKIA 1108 | C34: 54 | H34: 1483 | I34: 82944 | J34: =+VLOOKUP(I34,A:B,2,0)
A35: 55 | B35: TARJETA TELEFONIA PUBLICA US$3 | C35: 55 | H35: 1605 | I35: 105944 | J35: =+VLOOKUP(I35,A:B,2,0)
A36: 56 | B36: TARJETA TELEFONIA PUBLICA US$5 | C36: 56 | H36: 2396 | I36: 113950 | J36: =+VLOOKUP(I36,A:B,2,0)
A37: 58 | B37: TARJETA TELEFONIA SEMIPUBLICA US$20 | C37: 58 | H37: 2400 | I37: 113950 | J37: =+VLOOKUP(I37,A:B,2,0)
A38: 62 | B38: LISTO PACK GSM MOVISTAR 110 | C38: 62 | H38: 2416 | I38: 113950 | J38: =+VLOOKUP(I38,A:B,2,0)
A39: 66 | B39: GSM NOKIA 6230 | C39: 66 | H39: 2397 | I39: 113950 | J39: =+VLOOKUP(I39,A:B,2,0)
A40: 67 | B40: LISTO PACK GSM NOKIA 6230 | C40: 67 | H40: 2401 | I40: 113950 | J40: =+VLOOKUP(I40,A:B,2,0)
A41: 68 | B41: GSM MOTOROLA V3 SILVER | C41: 68 | H41: 2398 | I41: 113950 | J41: =+VLOOKUP(I41,A:B,2,0)
A42: 69 | B42: GSM SONY ERICSSON T290 | C42: 69 | H42: 2402 | I42: 113950 | J42: =+VLOOKUP(I42,A:B,2,0)
... A71: 103 | B71: VIRT GSM SONY ERICSSON K300 | C71: 103 | H71: 2804 | I71: 162092 | J71: =+VLOOKUP(I71,A:B,2,0)
A72: 104 | B72: VIRT GSM SONY ERICSSON P910A | C72: 104
A73: 105 | B73: GSM SIEMENS A76 | C73: 105
A74: 106 | B74: LISTO PACK GSM SIEMENS A76 | C74: 106
A75: 107 | B75: GSM ALCATEL 256 | C75: 107
A76: 108 | B76: GSM SONY ERICSSON W600 | C76: 108
A77: 109 | B77: LISTO PACK GSM ALCATEL 256 | C77: 109
A78: 110 | B78: LISTO PACK GSM SONY ERICSSON W600 | C78: 110
A79: 111 | B79: GSM BASE FIJA TECOM FGT850 | C79: 111
A80: 115 | B80: GSM SAMSUNG X636 | C80: 115
A81: 116 | B81: LISTO PACK GSM SAMSUNG X636 | C81: 116
A82: 117 | B82: GSM MOTOROLA C115 | C82: 117
A83: 118 | B83: LISTO PACK GSM MOTOROLA C115 | C83: 118
...

Sheet REFERENCIA
A1: REFERENCIA SICSA | B1: REFERENCIA SCL | F1: CANAL | G1: CANAL 2 | I1: ALMACEN
A2: MICROSIM 3FF POSPAGO 128K | B2: MICROSIM 3FF POSPAGO 128K | F2: Indirecto | G2: CANAL INDIRECTO | I2: Bodega Cuarentena | J2: NO DISPONIBLE
A3: MICROSIM 3FF PREPAGO 128K | B3: MICROSIM 3FF PREPAGO 128K | F3: Tienda Virtual | G3: CANAL INDIRECTO | I3: Bodega Produccion | J3: DISPONIBLE
A4: MICROSIM 3FF PREPAGO PROMO SALDO $0 (NUMERADA) 128K | B4: MICROSIM 3FF PREPAGO 128K (NUMERADA) | F4: Retail | G4: CANAL INDIRECTO | I4: Bodega Servicio Técnico | J4: NO DISPONIBLE
A5: MICROSIM 3FF PREPAGO PROMO SALDO $3 (NUMERADA) 128K | B5: MICROSIM 3FF PREPAGO 128K (NUMERADA) | F5: Directo | G5: CANAL DIRECTO | I5: Bunker Tarjetas | J5: DISPONIBLE
A6: MICROSIM PORTABILIDAD 3FF POSPAGO 128K | B6: MICROSIM 3FF POSPAGO 128K | F6: Cliente Final | G6: CANAL INDIRECTO | I6: Devolucion | J6: NO DISPONIBLE
A7: MICROSIM REPOSICION 3FF POSPAGO 128K | B7: MICROSIM 3FF POSPAGO 128K | F7: CANAL ONLINE | G7: CANAL DIRECTO | I7: Devolucion Delivery | J7: NO DISPONIBLE
A8: MINISIMCARD CUT POSPAGO | B8: MICROSIM 3FF POSPAGO | F8: BTB | G8: CANAL DIRECTO | I8: Matriz /tarjetas | J8: DISPONIBLE
A9: NANO SIMCARD 128K 4FF POSPAGO | B9: NANO SIMCARD 4FF POSPAGO 128K | F9: CONSORCIO SEGURIDAD | G9: CANAL DIRECTO | I9: Scrap | J9: NO DISPONIBLE
A10: NANO SIMCARD 4FF POSPAGO 128K | B10: NANO SIMCARD 4FF POSPAGO 128K | F10: 2083 | G10: CANAL DIRECTO | I10: Tienda Virtual | J10: DISPONIBLE
A11: NANO SIMCARD CUT 128K 4FF POSPAGO | B11: NANO SIMCARD 4FF POSPAGO 128K | F11: CASINDQUICAS1118 | G11: CANAL DIRECTO | I11: CONTINGENCIA GYE | J11: NO DISPONIBLE
A12: PACK 10 CHIPS PREP PROMO PLAST SALDO $0 (NUMERADA) 128K | B12: SIMCARD 2FF PREPAGO 128K (NUMERADA) | I12: SIN AUTENTICAR | J12: DISPONIBLE
A13: PACK 2 CHIPS PREP 2FF PROMO PLAST SALDO $0 NUM 128K DISTRIM | B13: SIMCARD 2FF PREPAGO 128K (NUMERADA) | I13: No Autentificado | J13: DISPONIBLE
A14: PACK 2 CHIPS PREP 2FF/3FF PROMO PLASTI SALDO $0 (NUMERADA) 128K | B14: SIMCARD 2FF PREPAGO 128K (NUMERADA) | I14: BODEGA CENTRAL | J14: DISPONIBLE
A15: PACK 2 CHIPS PREP 2FF/3FF PROMO PLASTI+SALDO $0 (NUMERADA) 128K | B15: SIMCARD 2FF PREPAGO 128K (NUMERADA) | I15: DELIVERY | J15: DISPONIBLE
A16: PACK 2 CHIPS PREP PROMO PLASTI SALDO $0 (NUMERADA) 128K | B16: SIMCARD 2FF PREPAGO 128K (NUMERADA) | I16: PRODUCCION | J16: DISPONIBLE
A17: PACK 5 CHIPS PREP PROMO PLASTI SALDO $0 (NUMERADA) 128K | B17: SIMCARD 2FF PREPAGO 128K (NUMERADA) | I17: MATERIA PRIMA | J17: DISPONIBLE
A18: SIMCARD 2FF POSTPAGO 128K | B18: SIMCARD 2FF POSTPAGO 128K
A19: SIMCARD 2FF POSTPAGO+128K | B19: SIMCARD 2FF POSTPAGO 128K
A20: SIMCARD 2FF PREPAGO 128K | B20: SIMCARD 2FF PREPAGO 128K
A21: SIMCARD 2FF PREPAGO PROMO SALDO $0 (NUMERADA) 128K | B21: SIMCARD 2FF PREPAGO 128K (NUMERADA)
A22: SIMCARD 2FF PREPAGO PROMO SALDO $0 (NUMERADA) 128K VIRTCORP | B22: SIMCARD 2FF PREPAGO 128K (NUMERADA)
A23: SIMCARD 2FF PREPAGO PROMOSALDO $0 (NUMERADA) 128K (PROYECTO | B23: SIMCARD 2FF PREPAGO 128K (NUMERADA)
A24: SIMCARD 2FF PREPAGO+128K | B24: SIMCARD 2FF PREPAGO 128K
A25: SIMCARD 2FF/3FF POSPAGO 128K | B25: SIMCARD 2FF POSTPAGO 128K
A26: SIMCARD 2FF/3FF POSPAGO+128K | B26: SIMCARD 2FF POSTPAGO 128K
A27: SIMCARD M2M POSPAGO GD BURTI | B27: SIMCARD M2M POSPAGO GD BURTI
A28: SIMCARD M2M POSPAGO GEMALTO | B28: SIMCARD M2M POSPAGO GEMALTO
A29: SIMCARD PORTABILIDAD (POSPAGO) 128K | B29: SIMCARD 2FF POSTPAGO 128K
... A189: HALFSIM TUENTI CELOFAN REPOSICION | B189: HALFSIM TUENTI CELOFAN REPOSICION

Sheet RESUMEN INVENTARIO T
A1: STATUS | B1: DISPONIBLE | N1: STATUS | O1: DISPONIBLE
A3: Suma de STOCK | C3: DISPONIBILIDAD | D3: ALMACEN | N3: Suma de STOCK | P3: DISPONIBILIDAD | Q3: ALMACEN
C4: STOCK DISPONIBLE | D4: STOCK DISPONIBLE | E4: STOCK DISPONIBLE | F4: STOCK DISPONIBLE | G4: STOCK DISPONIBLE | H4: Total general | I4: STOCK DISPONIBLE PRODUCIDO | P4: STOCK DISPONIBLE | Q4: STOCK DISPONIBLE | R4: Total general
A5: SCL 2 | B5: ARTICULO SCL | C5: Bunker Tarjetas | D5: Matriz /tarjetas | E5: Tienda Virtual | F5: Bodega Produccion | G5: SIN AUTENTICAR | N5: SCL 2 | O5: ARTICULO SCL | P5: Matriz /tarjetas | Q5: SIN AUTENTICAR
A6: 714 | B6: SIMCARD 2FF PREPAGO 128K | C6: 25 | H6: 25 | I6: =+C6+E6 | N6: 105944 | O6: DISTRIBUCION NUMERADA | P6: 22773 | R6: 22773
A7: 1534 | B7: SIMCARD M2M POSPAGO GEMALTO | C7: 23463 | E7: 3849 | H7: 27312 | I7: =+C7+E7 | N7: 162113 | O7: USIM MAXI | P7: 29840 | Q7: 149991 | R7: 179831
A8: 84948 | B8: USIM TUENTI PREPAGO (CELOFÁN) | C8: 1 | H8: 1 | I8: =+C8+E8 | N8: 162114 | O8: USIM AKI | Q8: 149991 | R8: 149991
A9: 96946 | B9: SUPER CHIP AUTOSERVICIOS INTERNET(numeradas) | C9: 1541 | H9: 1541 | I9: =+C9+E9 | N9: Total general | P9: 52613 | Q9: 299982 | R9: 352595
A10: 98948 | B10: SIM SUPER CHIP AUTOSERVICIOS (numeradas) | D10: 152 | H10: 152 | I10: =+C10+E10
A11: 105944 | B11: DISTRIBUCION NUMERADA | D11: 22773 | H11: 22773 | I11: =+C11+E11
A12: 113950 | B12: Usim Tuenti Prepago Celofán Numerada $5 SinSticker | C12: 2309 | H12: 2309 | I12: =+C12+E12
A13: 113950 | B13: Usim Tuenti Prepago Celofán Numerada $ 5.00 | C13: 12056 | E13: 12 | H13: 12068 | I13: =+C13+E13
A14: 113950 | B14: Usim Tuenti Prepago Celofán Numerada Freemium$3.00 | C14: 774 | H14: 774 | I14: =+C14+E14
A15: 113950 | B15: USIM GENERICA SIN AUTENTICAR | C15: 8 | H15: 8 | I15: =+C15+E15
A16: 140948 | B16: CHIP PREPAGO AUTOSERVICIOS TURISTA numerada | C16: 5 | H16: 5 | I16: =+C16+E16
A17: 162047 | B17: SIMCARD M2M 3FF LTE | C17: 9126 | E17: 1417 | H17: 10543 | I17: =+C17+E17
A18: 162046 | B18: SIMCARD M2M 2FF LTE | C18: 398 | D18: 9996 | E18: 2273 | H18: 12667 | I18: =+C18+E18
A19: 162048 | B19: SIMCARD M2M 4FF LTE | C19: 2755 | E19: 206 | H19: 2961 | I19: =+C19+E19
A20: 2748 | B20: USIM PORTABILIDAD MAXIPLUS | C20: 5524 | H20: 5524 | I20: =+C20+E20
A21: 2749 | B21: USIM REPOSICION MAXIPLUS | C21: 842 | H21: 842 | I21: =+C21+E21
A22: 2751 | B22: USIM PORTABILIDAD AKIMOVIL | C22: 2624 | H22: 2624 | I22: =+C22+E22
A23: 2752 | B23: USIM REPOSICION AKIMOVIL | C23: 592 | H23: 592 | I23: =+C23+E23
A24: 2747 | B24: USIM NUMERADA MAXIPLUS | C24: 15520 | H24: 15520 | I24: =+C24+E24
A25: 2750 | B25: USIM NUMERADA AKIMOVIL | C25: 483 | H25: 483 | I25: =+C25+E25
A26: 162092 | B26: CHIP PREPAGO $3 NUMERADO | C26: 60414 | F26: 39994 | H26: 100408 | I26: =+C26+E26
A27: 162089 | B27: CHIP PREPAGO $5 AUTOSERVICIO | C27: 2940 | H27: 2940 | I27: =+C27+E27
A28: 162090 | B28: CHIP PREPAGO $5 NUMERADO | C28: 9259 | H28: 9259 | I28: =+C28+E28
A29: 162082 | B29: SIM KITE M2M 2FF STANDARD | D29: 10000 | E29: 5179 | G29: 25000 | H29: 40179 | I29: =+C29+E29
A30: 162084 | B30: SIM KITE M2M 3FF HIGH TEMP | D30: 5000 | E30: 4975 | G30: 10000 | H30: 19975 | I30: =+C30+E30
A31: 162086 | B31: SIM KITE M2M 4FF | D31: 2500 | E31: 2498 | G31: 5000 | H31: 9998 | I31: =+C31+E31
A32: 162113 | B32: USIM MAXI | D32: 29840 | G32: 149991 | H32: 179831 | I32: =+C32+E32
A33: 162114 | B33: USIM AKI | G33: 149991 | H33: 149991 | I33: =+C33+E33
A34: 162119 | B34: ESIM EVOUCHERS CODE QR | C34: 129 | E34: 266 | H34: 395 | I34: =+C34+E34
A35: 162146 | B35: USIM MULTISIM MOVISTAR | C35: 70818 | D35: 92378 | E35: 10209 | H35: 173405 | I35: =+C35+E35
A36: 162142 | B36: Halfsim Tuenti Prepago Celofán Numerada $ 5.00 | C36: 24787 | H36: 24787 | I36: =+C36+E36
A37: 162142 | B37: HalfsimTuenti PrepagoCelofanNumerada $5sin sticker | C37: 17361 | H37: 17361 | I37: =+C37+E37
A38: 162142 | B38: Halfsim Tuenti Prepago Celofán Numerada $10.00 | C38: 1422 | H38: 1422 | I38: =+C38+E38
A39: 162142 | B39: Halfsim Tuenti Prepago Celofán Numerada $20.00 | C39: 963 | H39: 963 | I39: =+C39+E39+D39
A40: 162142 | B40: Halfsim Tuenti Prepago Celofán Numerada $25.00 | C40: 978 | H40: 978 | I40: =+C40+E40+D40
A41: 162120 | B41: HALF SIM MOVISTAR | D41: 494922 | G41: 179969 | H41: 674891 | I41: =+C41+E41+D41
...

Sheet RESUMEN DESPACHO
A4: CANAL 2 | B4: DESCRIPCION SCL 2 | C4: Suma de CANTIDAD
A5: CANAL INDIRECTO | B5: CHIP PREPAGO $3 NUMERADO | C5: 91075
A6: CANAL INDIRECTO | B6: CHIP PREPAGO $5 AUTOSERVICIO | C6: 3445
A7: CANAL INDIRECTO | B7: SIM KITE M2M 2FF STANDARD | C7: 8097
A8: CANAL INDIRECTO | B8: SIMCARD M2M POSPAGO GEMALTO | C8: 421
A9: CANAL INDIRECTO | B9: USIM TUENTI PREPAGO (CELOFÁN) | C9: 9768
A10: CANAL INDIRECTO | B10: Usim Tuenti Prepago Blíster Numerada $ 10.00 | C10: 204
A11: CANAL INDIRECTO | B11: Usim Tuenti Prepago Blíster Numerada $ 20.00 | C11: 28
A12: CANAL INDIRECTO | B12: Usim Tuenti Prepago Blíster Numerada $ 5.00 | C12: 19810
A13: CANAL INDIRECTO | B13: Usim Tuenti Prepago Celofán Numerada $ 5.00 | C13: 33100
A14: CANAL INDIRECTO | B14: Usim Tuenti Prepago Celofán Numerada $5 SinSticker | C14: 14434
A15: CANAL INDIRECTO | B15: SIM KITE M2M 3FF HIGH TEMP | C15: 26
A16: CANAL INDIRECTO | B16: USIM MULTISIM MOVISTAR | C16: 44514
... A36: CANAL DIRECTO | B36: USIM CHIP PREPAGO WIFI MOVIL $5 AUTOSERVICIO | C36: 1500
A37: Total general | C37: 263469
F540: 8959300320527010000 | G540: USIM MULTISIM POSPAGO | L540: 1 | M540: 1599 | N540: 81944
F541: 8959300320527160000 | G541: USIM MULTISIM POSPAGO | L541: 1 | M541: 1599 | N541: 81944
F542: 8959300320527160000 | G542: USIM MULTISIM POSPAGO | L542: 1 | M542: 1599 | N542: 81944
F543: 8959300320527160000 | G543: USIM MULTISIM POSPAGO | L543: 1 | M543: 1599 | N543: 81944

Sheet INVENTARIO
A1: ALMACEN | B1: DESCRIPCION | C1: ARTICULO DEL CLIENTE | D1: COD ARTICULO | E1: STOCK | F1: STATUS | G1: ARTICULO SCL | H1: SCL 2 | I1: DISPONIBILIDAD
A2: BODEGA CENTRAL | B2: HALFSIM AKIMOVIL SIM NUMERADA 15D | C2: 162524_07 | D2: 162524 | E2: 4000 | F2: DISPONIBLE | I2: STOCK DISPONIBLE
A3: BODEGA CENTRAL | B3: HALFSIM MAXIPLUS SIM NUMERADA 15D | C3: 162523_07 | D3: 162523 | E3: 2000 | F3: DISPONIBLE | I3: STOCK DISPONIBLE
A4: BODEGA CENTRAL | B4: HALFSIM MAXIPLUS SIM NUMERADA 30D | C4: 162523_08 | D4: 162523 | E4: 2000 | F4: DISPONIBLE | I4: STOCK DISPONIBLE
A5: BODEGA CENTRAL | B5: HALFSIM TIGO | C5: 163140 | D5: 163140 | E5: 1999 | F5: DISPONIBLE | I5: STOCK DISPONIBLE
A6: MATERIA PRIMA | B6: ESIM TIGO DIGITAL | C6: 163141 | D6: 163141 | E6: 139986 | F6: DISPONIBLE | I6: STOCK DISPONIBLE
A7: MATERIA PRIMA | B7: HALFSIM KITE M2M 2FF DEVICE CONTROL BLANCA | C7: 162594_01 | D7: 162594 | E7: 10000 | F7: DISPONIBLE | I7: STOCK DISPONIBLE
A8: PRODUCCION | B8: HALFSIM TIGO PORTABILIDAD | C8: 163140_06 | D8: 163140 | E8: 19999 | F8: DISPONIBLE | I8: STOCK DISPONIBLE
A9: BODEGA CENTRAL | B9: ESIM MAXIPLUS | C9: 162822 | D9: 162822 | E9: 1946 | F9: DISPONIBLE | I9: STOCK DISPONIBLE
A10: BODEGA CENTRAL | B10: HALFSIM KITE M2M 4FF DEVICE CONTROL TELEFONICA | C10: 162699 | D10: 162699 | E10: 5199 | F10: DISPONIBLE | I10: STOCK DISPONIBLE
A11: BODEGA CENTRAL | B11: HALFSIM TIGO CHIP PREPAGO $3 WP CANAL DIRECTO NUMERADO | C11: 163140_03 | D11: 163140 | E11: 4999 | F11: DISPONIBLE | I11: STOCK DISPONIBLE
A12: BODEGA CENTRAL | B12: HALFSIM TIGO CHIP PREPAGO $3 WP NUMERADO | C12: 163140_02 | D12: 163140 | E12: 219814 | F12: DISPONIBLE | I12: STOCK DISPONIBLE
A13: BODEGA CENTRAL | B13: HALFSIM TIGO PORTABILIDAD | C13: 163140_06 | D13: 163140 | E13: 37576 | F13: DISPONIBLE | I13: STOCK DISPONIBLE
... A54: MATERIA PRIMA | B54: ESIM AKIMOVIL | C54: 162823 | D54: 162823 | E54: 4998 | F54: DISPONIBLE | I54: STOCK DISPONIBLE

Sheet DESPACHOS 20 DIAS
A1: FECHA | B1: PEDIDO | C1: CLAVE FLEXNET | D1: CLAVE CLIENTE | E1: DESCRIPCION | F1: CANTIDAD | G1: VALORADO | H1: PMP | I1: CODIGO DESPACHO | J1: CLIENTE | K1: RUC | L1: CIUDAD | M1: CANAL | N1: CANAL 2 | O1: DESCRIPCION SCL 2 | P1: SCL
A2: 02/10/2026 | B2: 16500487 | C2: 163140 | D2: 163140 | E2: HALFSIM TIGO | F2: 1 | G2: 0.69 | H2: 0.69 | J2: BRITO ORTIZ FAUSTO DIEGO_BRITO ORTIZ FAUSTO DIEGO | K2: 1704454394001 | M2: BTB | N2: CANAL DIRECTO
A3: 02/10/2026 | B3: 16500487 | C3: 163140 | D3: 163140 | E3: HALFSIM TIGO | F3: 1 | G3: 0.69 | H3: 0.69 | J3: BRITO ORTIZ FAUSTO DIEGO_BRITO ORTIZ FAUSTO DIEGO | K3: 1704454394001 | M3: BTB | N3: CANAL DIRECTO
A4: 02/10/2026 | B4: 97720760 | C4: 163140 | D4: 163140 | E4: HALFSIM TIGO | F4: 1 | G4: 0.69 | H4: 0.69 | J4: María Eugenia Vera Cevallos | K4: 1310783459 | L4: Manta | M4: Cliente Final | N4: CANAL INDIRECTO
A5: 02/10/2026 | B5: 97723550 | C5: 163140 | D5: 163140 | E5: HALFSIM TIGO | F5: 1 | G5: 0.69 | H5: 0.69 | J5: Andy Gabriel Panezo Piza | K5: 0957668056 | L5: Quito | M5: Cliente Final | N5: CANAL INDIRECTO
A6: 02/10/2026 | B6: 97726248 | C6: 163140 | D6: 163140 | E6: HALFSIM TIGO | F6: 1 | G6: 0.69 | H6: 0.69 | J6: LILIANA MARGOTH YANZA VILLAGRAN | K6: 1723345813 | L6: Quito | M6: Cliente Final | N6: CANAL INDIRECTO
A7: 02/10/2026 | B7: 97726432 | C7: 163140 | D7: 163140 | E7: HALFSIM TIGO | F7: 1 | G7: 0.69 | H7: 0.69 | J7: Lisbeth Carolina Saltos Proaño | K7: 1004824965 | L7: Ibarra | M7: Cliente Final | N7: CANAL INDIRECTO
A8: 02/10/2026 | B8: 97727391 | C8: 163140 | D8: 163140 | E8: HALFSIM TIGO | F8: 1 | G8: 0.69 | H8: 0.69 | J8: William Andrés Ibadango Cuascota | K8: 1004293526 | L8: Ibarra | M8: Cliente Final | N8: CANAL INDIRECTO
A9: 02/10/2026 | B9: 16501055 | C9: 163140 | D9: 163140 | E9: HALFSIM TIGO | F9: 22 | G9: 15.18 | H9: 0.69 | J9: KEVIN FERNANDEZ_CEPAPRODUCCION CIA LTDA | K9: 1792199689001 | M9: BTB | N9: CANAL DIRECTO
A10: 02/10/2026 | B10: 16501610 | C10: 163140 | D10: 163140 | E10: HALFSIM TIGO | F10: 1 | G10: 0.69 | H10: 0.69 | J10: GALO ACOSTA_PUBLIMARKCACORPORACION EMPRESARIAL S A S | K10: 1793186084001 | M10: BTB | N10: CANAL DIRECTO
A11: 02/10/2026 | B11: 16501730 | C11: 163140 | D11: 163140 | E11: HALFSIM TIGO | F11: 1 | G11: 0.69 | H11: 0.69 | J11: UMAQUINGA SERRANO DARIO XAVIER_UMAQUINGA SERRANO DARIO XAVIER | K11: 1717964009001 | M11: BTB | N11: CANAL DIRECTO
A12: 02/10/2026 | B12: 16501749 | C12: 163140 | D12: 163140 | E12: HALFSIM TIGO | F12: 1 | G12: 0.69 | H12: 0.69 | J12: NARANJO CRUZ GUILLERMO MOISES_NARANJO CRUZ GUILLERMO MOISES | K12: 0952555274001 | M12: BTB | N12: CANAL DIRECTO
A13: 02/10/2026 | B13: 16501782 | C13: 163140 | D13: 163140 | E13: HALFSIM TIGO | F13: 1 | G13: 0.69 | H13: 0.69 | J13: RIVERA VALENZUELA MARIO AUGUSTO_RIVERA VALENZUELA MARIO AUGUSTO | K13: 1711382109001 | M13: BTB | N13: CANAL DIRECTO
A14: 02/10/2026 | B14: 16501800 | C14: 163140 | D14: 163140 | E14: HALFSIM TIGO | F14: 14 | G14: 9.66 | H14: 0.69 | J14: TV CABLE SANTA ANA TVCABSA S A _TV CABLE SANTA ANA TVCABSA S A | K14: 1791275101001 | M14: BTB | N14: CANAL DIRECTO
